Workbook

Sheet Datos
A1: MEMORIA DE CÁLCULO – INSTALACIONES SANITARIAS, AGUAS LLUVIAS Y SISTEMA DE TRATAMIENTO IN SITU
A2: DATOS GENERALES, NORMATIVA Y PROGRAMA ARQUITECTÓNICO
A3: Proyecto: Vivienda campestre unifamiliar – Restrepo (Valle del Cauca) | Rev. 0 | PENDIENTE: ajustar con planos arquitectónicos (D:\trabajo\proyecto\en curso\casa Restrepo)
B5: Leyenda: celdas AMARILLAS con texto AZUL = datos de entrada editables. Texto NEGRO = fórmulas. Texto VERDE = vínculos a otras hojas. Verificaciones en verde (CUMPLE) / rojo (NO CUMPLE).
B6: PENDIENTE: ajustar con planos arquitectónicos (D:\trabajo\proyecto\en curso\casa Restrepo)
A8: 1. IDENTIFICACIÓN DEL PROYECTO
A9: Ítem | B9: Descripción | C9: Símbolo | D9: Valor | E9: Unidad | F9: Referencia normativa / criterio / observación
A10: 1.1 | B10: Proyecto | D10: Vivienda campestre unifamiliar
A11: 1.2 | B11: Municipio / departamento | D11: Restrepo, Valle del Cauca
A12: 1.3 | B12: Zona | D12: Rural – suelo suburbano / rural (verificar EOT Restrepo) | F12: Verificar uso del suelo en EOT municipal
A13: 1.4 | B13: Altitud media del predio | C13: z | D13: 1400 | E13: msnm | F13: PENDIENTE: confirmar con levantamiento topográfico
A14: 1.5 | B14: Temperatura media anual | C14: T | D14: 20 | E14: °C | F14: Valor de referencia regional; confirmar con estación IDEAM más cercana
A15: 1.6 | B15: Autoridad ambiental | D15: CVC – Corporación Autónoma Regional del Valle del Cauca | F15: Permiso de vertimientos: Decreto 1076/2015
A16: 1.7 | B16: Fuente de abastecimiento | D16: Acueducto veredal / rural (punto de conexión) | F16: PENDIENTE: certificado de disponibilidad del prestador
A17: 1.8 | B17: Disposición de aguas residuales | D17: Sistema individual in situ: TG + TS + FAFA + campo de infiltración | F17: Sin red de alcantarillado público disponible
A18: 1.9 | B18: Revisión / fecha | D18: Rev. 0 – borrador para ajuste con planos
A20: 2. PROGRAMA ARQUITECTÓNICO (EDITAR SEGÚN PLANOS)
A21: Ítem | B21: Descripción | C21: Símbolo | D21: Valor | E21: Unidad | F21: Referencia normativa / criterio / observación
A22: 2.1 | B22: Alcobas principales | C22: Na | D22: 3 | E22: und | F22: PENDIENTE: ajustar con planos arquitectónicos (D:\trabajo\proyecto\en curso\casa Restrepo)
A23: 2.2 | B23: Alcobas de servicio | C23: Nas | D23: 1 | E23: und | F23: PENDIENTE: ajustar con planos arquitectónicos (D:\trabajo\proyecto\en curso\casa Restrepo)
A24: 2.3 | B24: Baños completos (sanitario + lavamanos + ducha) | C24: Nbc | D24: 2 | E24: und | F24: PENDIENTE: ajustar con planos arquitectónicos (D:\trabajo\proyecto\en curso\casa Restrepo)
A25: 2.4 | B25: Baños sociales (sanitario + lavamanos) | C25: Nbs | D25: 1 | E25: und | F25: PENDIENTE: ajustar con planos arquitectónicos (D:\trabajo\proyecto\en curso\casa Restrepo)
A26: 2.5 | B26: Cocinas (lavaplatos) | C26: Nc | D26: 1 | E26: und | F26: PENDIENTE: ajustar con planos arquitectónicos (D:\trabajo\proyecto\en curso\casa Restrepo)
A27: 2.6 | B27: Zonas de ropas (lavadero + lavadora) | C27: Nr | D27: 1 | E27: und | F27: PENDIENTE: ajustar con planos arquitectónicos (D:\trabajo\proyecto\en curso\casa Restrepo)
A28: 2.7 | B28: Zona BBQ / kiosco (lavaplatos exterior) | C28: Nbbq | D28: 1 | E28: und | F28: PENDIENTE: ajustar con planos arquitectónicos (D:\trabajo\proyecto\en curso\casa Restrepo)
A29: 2.8 | B29: Llaves de jardín / manguera | C29: Nj | D29: 2 | E29: und | F29: PENDIENTE: ajustar con planos arquitectónicos (D:\trabajo\proyecto\en curso\casa Restrepo)
A30: 2.9 | B30: Número de pisos | C30: Np | D30: 1 | E30: und | F30: PENDIENTE: ajustar con planos arquitectónicos (D:\trabajo\proyecto\en curso\casa Restrepo)
A31: 2.10 | B31: Área de cubierta (proyección horizontal) | C31: Ac | D31: 180 | E31: m² | F31: PENDIENTE: ajustar con planos arquitectónicos (D:\trabajo\proyecto\en curso\casa Restrepo)
A32: 2.11 | B32: Área de patios / terrazas duras drenadas | C32: Ap | D32: 40 | E32: m² | F32: PENDIENTE: ajustar con planos arquitectónicos (D:\trabajo\proyecto\en curso\casa Restrepo)
A33: 2.12 | B33: Área de zonas verdes / jardín con riego | C33: Av | D33: 300 | E33: m² | F33: PENDIENTE: ajustar con planos arquitectónicos (D:\trabajo\proyecto\en curso\casa Restrepo)
A35: 3. MARCO NORMATIVO APLICADO
B36: • RAS 2000 – Reglamento Técnico del Sector de Agua Potable y Saneamiento Básico (Res. 1096/2000): Título A (nivel de complejidad), Título B (población, dotación, caudales), Título D (alcantarillados), Título E (tratamiento de aguas residuales – sistemas in situ).
B37: • Resolución 0330 de 2017 (MinVivienda), modificada por la Res. 0799 de 2021 – reglamento técnico vigente (dotación neta máxima, pérdidas, coeficientes de diseño). Prevalece sobre RAS 2000 donde difieren.
B38: • NTC 1500:2017 – Código colombiano de instalaciones hidráulicas y sanitarias (aparatos, presiones, unidades de consumo y de descarga, ventilación, aguas lluvias).
B39: • Decreto 1077 de 2015 (sector vivienda) y Decreto 1076 de 2015 (sector ambiente – permiso de vertimientos ante la CVC).
B40: • Resolución 699 de 2021 (MinAmbiente) – vertimientos de ARD tratadas al suelo.
B41: • Criterios complementarios de referencia: NBR 7229/1993 y NBR 13969/1997 (tanque séptico y filtro anaerobio, base de las fórmulas del RAS 2000 Título E); USPHS Manual of Septic-Tank Practice (1967) – percolación; IPC (International Plumbing Code) – tablas de capacidad de desagües y bajantes pluviales.
B43: NOTA: los valores de tablas normativas transcritos en la hoja "Tablas" deben verificarse contra la edición vigente de cada norma antes de radicar la memoria.

Sheet Poblacion
A1: MEMORIA DE CÁLCULO – INSTALACIONES SANITARIAS, AGUAS LLUVIAS Y SISTEMA DE TRATAMIENTO IN SITU
A2: CÁLCULO DE POBLACIÓN DE DISEÑO POR USOS Y NIVEL DE COMPLEJIDAD (RAS 2000)
A3: Proyecto: Vivienda campestre unifamiliar – Restrepo (Valle del Cauca) | Rev. 0 | PENDIENTE: ajustar con planos arquitectónicos (D:\trabajo\proyecto\en curso\casa Restrepo)
B5: La vivienda unifamiliar no requiere proyección demográfica (RAS 2000 B.2.2): la población se fija por capacidad de ocupación (alcobas) y se discrimina por tipo de uso/ocupante (permanente, servicio, flotante, empleados), conforme a RAS 2000 B.2.3 (usos) y B.2.4 (dotación por uso).
A7: 1. PARÁMETROS DE OCUPACIÓN
A8: Ítem | B8: Descripción | C8: Símbolo | D8: Valor | E8: Unidad | F8: Referencia normativa / criterio / observación
A9: 1.1 | B9: Ocupación por alcoba principal | C9: ha | D9: 2 | E9: hab/alcoba | F9: Criterio usual de diseño de instalaciones internas (2 hab/alcoba)
A10: 1.2 | B10: Ocupación por alcoba de servicio | C10: hs | D10: 1 | E10: hab/alcoba | F10: Criterio usual de diseño
A11: 1.3 | B11: Población flotante – visitantes que pernoctan (ocupación pico fin de semana) | C11: Nv | D11: 4 | E11: hab | F11: Uso recreacional campestre; PENDIENTE confirmar con propietario
A12: 1.4 | B12: Población flotante – empleados sin pernoctación (mayordomo, jardinero, aseo) | C12: Ne | D12: 2 | E12: emp | F12: PENDIENTE confirmar con propietario
A14: 2. POBLACIÓN DE DISEÑO POR USOS
A15: Ítem | B15: Descripción | C15: Símbolo | D15: Valor | E15: Unidad | F15: Referencia normativa / criterio / observación
A16: 2.1 | B16: Población residente permanente = Na × ha | C16: Pr | D16: =Datos!$D$22*$D$9 -> 6 | E16: hab | F16: RAS 2000 B.2.3 – uso residencial
A17: 2.2 | B17: Población de servicio doméstico = Nas × hs | C17: Ps | D17: =Datos!$D$23*$D$10 -> 1 | E17: hab | F17: Uso residencial (pernocta)
A18: 2.3 | B18: Población flotante que pernocta | C18: Pf | D18: =$D$11 -> 4 | E18: hab | F18: RAS 2000 B.2.3 – población flotante
A19: 2.4 | B19: Población con pernoctación (diseño residencial) = Pr + Ps + Pf | C19: Pp | D19: =$D$16+$D$17+$D$18 -> 11 | E19: hab | F19: Se diseña para ocupación pico (casa campestre)
A20: 2.5 | B20: Población flotante diurna (empleados) | C20: Pe | D20: =$D$12 -> 2 | E20: emp | F20: Uso de servicio – dotación reducida
A21: 2.6 | B21: Población total de diseño = Pp + Pe | C21: Pd | D21: =$D$19+$D$20 -> 13 | E21: hab
A23: 3. NIVEL DE COMPLEJIDAD DEL SISTEMA (RAS 2000 TABLA A.3.1)
A24: Ítem | B24: Descripción | C24: Símbolo | D24: Valor | E24: Unidad | F24: Referencia normativa / criterio / observación
A25: 3.1 | B25: Índice de nivel según población servida | C25: i | D25: =MATCH($D$21,Tablas!$B$49:$B$52,1) -> 1 | F25: Bajo ≤ 2.500 hab; Medio 2.501–12.500; Medio alto 12.501–60.000; Alto > 60.000
A26: 3.2 | B26: Nivel de complejidad | C26: NC | D26: =INDEX(Tablas!$A$49:$A$52,$D$25) -> BAJO | F26: Sistema individual unifamiliar → BAJO
A27: 3.3 | B27: Período de diseño de referencia (RAS 2000) | C27: n | D27: =INDEX(Tablas!$H$49:$H$52,$D$25) -> 15 | E27: años | F27: Res. 0330/2017 fija 25 años para sistemas nuevos; en vivienda la población no varía con el horizonte
A29: 4. DOTACIÓN NETA POR USO (RAS 2000 B.2.4 – RES. 0330/2017 ART. 43)
A30: Ítem | B30: Descripción | C30: Símbolo | D30: Valor | E30: Unidad | F30: Referencia normativa / criterio / observación
A31: 4.1 | B31: Dotación neta mínima RAS 2000 para el nivel | C31: dmín | D31: =INDEX(Tablas!$C$49:$C$52,$D$25) -> 100 | E31: L/hab·d | F31: RAS 2000 Tabla B.2.2
A32: 4.2 | B32: Dotación neta máxima RAS 2000 para el nivel | C32: dmáx | D32: =INDEX(Tablas!$D$49:$D$52,$D$25) -> 150 | E32: L/hab·d | F32: RAS 2000 Tabla B.2.2
A33: 4.3 | B33: Dotación neta base seleccionada (RAS 2000) | C33: d0 | D33: 120 | E33: L/hab·d | F33: Entre dmín y dmáx según usos de la vivienda
A34: 4.4 | B34: Dotación base dentro del rango RAS 2000 | C34: ✓ | D34: =IF(AND($D$33>=$D$31,$D$33<=$D$32),"CUMPLE","NO CUMPLE") -> CUMPLE | F34: RAS 2000 Tabla B.2.2
A35: 4.5 | B35: Corrección por clima (T media) | C35: Δc | D35: =IF(Datos!$D$14>28,0.15,IF(Datos!$D$14>=20,0.1,0)) -> 0.1 | E35: % | F35: RAS 2000 Tabla B.2.3: cálido (>28 °C) +15 %; templado (20–28 °C) +10 %; frío (<20 °C) sin corrección
A36: 4.6 | B36: Dotación neta corregida RAS 2000 = d0 × (1 + Δc) | C36: dRAS | D36: =$D$33*(1+$D$35) -> 132 | E36: L/hab·d
A37: 4.7 | B37: Dotación neta máxima Res. 0330/2017 según altitud | C37: d0330 | D37: =IF(Datos!$D$13>2000,120,IF(Datos!$D$13>=1000,130,140)) -> 130 | E37: L/hab·d | F37: Art. 43: >2.000 msnm: 120; 1.000–2.000 msnm: 130; <1.000 msnm: 140 L/hab·d
A38: 4.8 | B38: Dotación neta adoptada – uso residencial = MÍN(dRAS; d0330) | C38: dn | D38: =MIN($D$36,$D$37) -> 130 | E38: L/hab·d | F38: Se adopta el menor valor (norma vigente prevalece)
A39: 4.9 | B39: Dotación neta – empleados sin pernoctación | C39: de | D39: 50 | E39: L/emp·d | F39: Criterio para personal de jornada diurna (NBR 7229 – ocupantes temporales: 50 L/pers·d)
A41: 5. CONSUMO NETO POR USOS
B42: Uso / tipo de ocupante | C42: Población (hab) | D42: Dotación neta (L/hab·d) | E42: Consumo neto (L/d)
B43: Residentes permanentes | C43: =$D$16 -> 6 | D43: =$D$38 -> 130 | E43: =C43*D43 -> 780
B44: Servicio doméstico | C44: =$D$17 -> 1 | D44: =$D$38 -> 130 | E44: =C44*D44 -> 130
B45: Flotante – visitantes que pernoctan | C45: =$D$18 -> 4 | D45: =$D$38 -> 130 | E45: =C45*D45 -> 520
B46: Flotante – empleados diurnos | C46: =$D$20 -> 2 | D46: =$D$39 -> 50 | E46: =C46*D46 -> 100
...

Sheet Caudales_AR
A1: MEMORIA DE CÁLCULO – INSTALACIONES SANITARIAS, AGUAS LLUVIAS Y SISTEMA DE TRATAMIENTO IN SITU
A2: CAUDALES DE AGUAS RESIDUALES DOMÉSTICAS (ARD) Y CONTRIBUCIÓN AL SISTEMA IN SITU
A3: Proyecto: Vivienda campestre unifamiliar – Restrepo (Valle del Cauca) | Rev. 0 | PENDIENTE: ajustar con planos arquitectónicos (D:\trabajo\proyecto\en curso\casa Restrepo)
A6: 1. COEFICIENTE DE RETORNO
A7: Ítem | B7: Descripción | C7: Símbolo | D7: Valor | E7: Unidad | F7: Referencia normativa / criterio / observación
A8: 1.1 | B8: Coeficiente de retorno | C8: CR | D8: 0.85 | F8: Res. 0330/2017 (CR = 0,85); RAS 2000 Tabla D.3.1 (0,70–0,85)
A10: 2. CAUDALES DE ARD
A11: Ítem | B11: Descripción | C11: Símbolo | D11: Valor | E11: Unidad | F11: Referencia normativa / criterio / observación
A12: 2.1 | B12: Caudal medio diario de ARD = CR × Consumo neto / 86.400 | C12: QmdAR | D12: =$D$8*Poblacion!$E$47/86400 -> 0.015052083 | E12: L/s | F12: RAS 2000 D.3.2
A13: 2.2 | B13: Factor de mayoración de Harmon F = 1 + 14 / (4 + √(P/1000)) | C13: F | D13: =1+14/(4+SQRT(Poblacion!$D$21/1000)) -> 4.4029996 | F13: RAS 2000 D.3.2.4 (límite superior para poblaciones muy pequeñas)
A14: 2.3 | B14: Caudal máximo horario de ARD = F × QmdAR | C14: QMHAR | D14: =$D$13*$D$12 -> 0.066274317 | E14: L/s
A15: 2.4 | B15: Aporte por infiltración | C15: Qinf | D15: 0 | E15: L/s | F15: Red interna nueva y estanca: no aplica
A16: 2.5 | B16: Aporte por conexiones erradas | C16: Qce | D16: 0 | E16: L/s | F16: Aguas lluvias en red separada: no aplica
A17: 2.6 | B17: Caudal de diseño ARD (por población) | C17: QdAR | D17: =$D$14+$D$15+$D$16 -> 0.066274317 | E17: L/s | F17: Referencia; los desagües internos se dimensionan por UD (Hunter)
A19: 3. CONTRIBUCIÓN DIARIA AL SISTEMA IN SITU (RAS 2000 TÍTULO E / NBR 7229 TABLA 1)
A20: Ítem | B20: Descripción | C20: Símbolo | D20: Valor | E20: Unidad | F20: Referencia normativa / criterio / observación
A21: 3.1 | B21: Ocupantes permanentes (con pernoctación) | C21: Np | D21: =Poblacion!$D$19 -> 11 | E21: hab | F21: Hoja Poblacion
A22: 3.2 | B22: Contribución de ARD por ocupante permanente | C22: Cp | D22: 130 | E22: L/hab·d | F22: NBR 7229 Tabla 1 – residencia estándar medio
A23: 3.3 | B23: Contribución de lodo fresco por ocupante permanente | C23: Lfp | D23: 1 | E23: L/hab·d | F23: NBR 7229 Tabla 1
A24: 3.4 | B24: Ocupantes temporales (empleados diurnos) | C24: Nt | D24: =Poblacion!$D$20 -> 2 | E24: emp | F24: Hoja Poblacion
A25: 3.5 | B25: Contribución de ARD por ocupante temporal | C25: Ct | D25: 50 | E25: L/emp·d | F25: NBR 7229 Tabla 1 – ocupantes temporales
A26: 3.6 | B26: Contribución de lodo fresco por ocupante temporal | C26: Lft | D26: 0.2 | E26: L/emp·d | F26: NBR 7229 Tabla 1
A27: 3.7 | B27: Contribución diaria = Np·Cp + Nt·Ct | C27: Cd | D27: =$D$21*$D$22+$D$24*$D$25 -> 1530 | E27: L/d
A28: 3.8 | B28: Lodo fresco total = Np·Lfp + Nt·Lft | C28: ΣLf | D28: =$D$21*$D$23+$D$24*$D$26 -> 11.4 | E28: L/d
A29: 3.9 | B29: Contribución por coeficiente de retorno = CR × dn | C29: CR·dn | D29: =$D$8*Poblacion!$D$38 -> 110.5 | E29: L/hab·d | F29: Comparación
A30: 3.10 | B30: Contribución adoptada ≥ CR × dotación neta (diseño conservador) | C30: ✓ | D30: =IF($D$22>=$D$29,"CUMPLE","NO CUMPLE") -> CUMPLE
A32: 4. CARGAS CONTAMINANTES (RAS 2000 TÍTULO E – APORTES PER CÁPITA)
A33: Ítem | B33: Descripción | C33: Símbolo | D33: Valor | E33: Unidad | F33: Referencia normativa / criterio / observación
A34: 4.1 | B34: Aporte per cápita DBO5 – ocupante permanente | D34: 50 | E34: g/hab·d | F34: RAS 2000 Título E – valor sugerido 50 g/hab·d
A35: 4.2 | B35: Aporte per cápita SST – ocupante permanente | D35: 50 | E35: g/hab·d | F35: RAS 2000 Título E – valor sugerido 50 g/hab·d
A36: 4.3 | B36: Aporte DBO5 – ocupante temporal | D36: 20 | E36: g/emp·d | F36: Criterio: permanencia parcial (≈ 40 %)
A37: 4.4 | B37: Aporte SST – ocupante temporal | D37: 20 | E37: g/emp·d | F37: Criterio: permanencia parcial (≈ 40 %)
A38: 4.5 | B38: Carga de DBO5 | C38: WDBO | D38: =$D$21*$D$34+$D$24*$D$36 -> 590 | E38: g/d
A39: 4.6 | B39: Carga de SST | C39: WSST | D39: =$D$21*$D$35+$D$24*$D$37 -> 590 | E39: g/d
A40: 4.7 | B40: Concentración afluente DBO5 = W / Cd | C40: DBOa | D40: =$D$38*1000/$D$27 -> 385.62092 | E40: mg/L
A41: 4.8 | B41: Concentración afluente SST = W / Cd | C41: SSTa | D41: =$D$39*1000/$D$27 -> 385.62092 | E41: mg/L

Sheet UD_Desagues
A1: MEMORIA DE CÁLCULO – INSTALACIONES SANITARIAS, AGUAS LLUVIAS Y SISTEMA DE TRATAMIENTO IN SITU
A2: UNIDADES DE DESCARGA, DERIVACIONES, BAJANTES, COLECTORES Y VENTILACIÓN (NTC 1500)
A3: Proyecto: Vivienda campestre unifamiliar – Restrepo (Valle del Cauca) | Rev. 0 | PENDIENTE: ajustar con planos arquitectónicos (D:\trabajo\proyecto\en curso\casa Restrepo)
B5: Cantidades vinculadas al programa arquitectónico (hoja Datos). UD por aparato según NTC 1500 / IPC Tabla 709.1.
B6: PENDIENTE: ajustar con planos arquitectónicos (D:\trabajo\proyecto\en curso\casa Restrepo)
A8: 1. UNIDADES DE DESCARGA POR APARATO
A9: Aparato | B9: Cantidad (und) | C9: UD por aparato | D9: UD totales | E9: Ø mín. desagüe | F9: Descarga a
A10: Sanitario con tanque | B10: =Datos!$D$24+Datos!$D$25 -> 3 | C10: 4 | D10: =B10*C10 -> 12 | E10: 4" | F10: Tanque séptico
A11: Lavamanos | B11: =Datos!$D$24+Datos!$D$25 -> 3 | C11: 1 | D11: =B11*C11 -> 3 | E11: 1-1/2" | F11: Tanque séptico
A12: Ducha | B12: =Datos!$D$24 -> 2 | C12: 2 | D12: =B12*C12 -> 4 | E12: 2" | F12: Tanque séptico
A13: Sifón de piso (baños completos y ropas) | B13: =Datos!$D$24+Datos!$D$27 -> 3 | C13: 2 | D13: =B13*C13 -> 6 | E13: 2" | F13: Tanque séptico
A14: Lavadero | B14: =Datos!$D$27 -> 1 | C14: 2 | D14: =B14*C14 -> 2 | E14: 2" | F14: Tanque séptico
A15: Lavadora | B15: =Datos!$D$27 -> 1 | C15: 3 | D15: =B15*C15 -> 3 | E15: 2" | F15: Tanque séptico
A16: Lavaplatos cocina | B16: =Datos!$D$26 -> 1 | C16: 2 | D16: =B16*C16 -> 2 | E16: 2" | F16: Trampa de grasas
A17: Lavaplatos BBQ / kiosco | B17: =Datos!$D$28 -> 1 | C17: 2 | D17: =B17*C17 -> 2 | E17: 2" | F17: Trampa de grasas
A18: TOTAL | D18: =SUM(D10:D17) -> 34
A19: UD que descargan a la trampa de grasas | D19: =SUMIF(F10:F17,"Trampa de grasas",D10:D17) -> 4
A21: 2. VERIFICACIÓN DE CAPACIDAD DE DESAGÜES
A22: Elemento | B22: UD de diseño | C22: Ø adoptado | D22: Pendiente S | E22: Capacidad (UD) | F22: Verificación
A23: Ramal de baño completo (WC + lavamanos + ducha + sifón) | B23: =C10+C11+C12+C13 -> 9 | C23: 4" | D23: — | E23: =INDEX(Tablas!$B$66:$B$70,MATCH(C23,Tablas!$A$66:$A$70,0)) -> 160 | F23: =IF(B23<=E23,"CUMPLE","NO CUMPLE") -> CUMPLE
A24: Ramal cocina + BBQ → trampa de grasas | B24: =$D$19 -> 4 | C24: 2" | D24: — | E24: =INDEX(Tablas!$B$66:$B$70,MATCH(C24,Tablas!$A$66:$A$70,0)) -> 6 | F24: =IF(B24<=E24,"CUMPLE","NO CUMPLE") -> CUMPLE
A25: Ramal zona de ropas (lavadero + lavadora + sifón) | B25: =C14+C15+C13 -> 7 | C25: 3" | D25: — | E25: =INDEX(Tablas!$B$66:$B$70,MATCH(C25,Tablas!$A$66:$A$70,0)) -> 20 | F25: =IF(B25<=E25,"CUMPLE","NO CUMPLE") -> CUMPLE
A26: Bajante sanitaria (aplica si Np > 1) | B26: =$D$18 -> 34 | C26: 4" | D26: — | E26: =INDEX(Tablas!$C$66:$C$70,MATCH(C26,Tablas!$A$66:$A$70,0)) -> 240 | F26: =IF(B26<=E26,"CUMPLE","NO CUMPLE") -> CUMPLE
A27: Colector principal → tanque séptico | B27: =$D$18 -> 34 | C27: 4" | D27: 0.02 | E27: =IF(D27>=0.02,INDEX(Tablas!$E$66:$E$70,MATCH(C27,Tablas!$A$66:$A$70,0)),INDEX(Tablas!$D$66:$D$70,MATCH(C27,Tablas!$A$66:$A$70,0))) -> 216 | F27: =IF(B27<=E27,"CUMPLE","NO CUMPLE") -> CUMPLE
A30: 3. VERIFICACIONES COMPLEMENTARIAS
A31: Ø de ramal/colector que recibe sanitarios ≥ 3" (se adopta 4") | D31: =IF(AND(INDEX(Tablas!$B$57:$B$61,MATCH(C23,Tablas!$A$57:$A$61,0))>=3,INDEX(Tablas!$B$57:$B$61,MATCH($C$27,Tablas!$A$57:$A$61,0))>=3),"CUMPLE","NO CUMPLE") -> CUMPLE | E31: NTC 1500
A32: Pendiente del colector entre 1 % y 4 % | D32: =IF(AND($D$27>=0.01,$D$27<=0.04),"CUMPLE","NO CUMPLE") -> CUMPLE | E32: NTC 1500 – desagües horizontales
A33: Ø de la columna de ventilación principal | D33: 2" | E33: Lista desplegable
A34: Ventilación ≥ MÁX(1-1/2"; ½ Ø bajante/colector) | D34: =IF(INDEX(Tablas!$B$57:$B$61,MATCH($D$33,Tablas!$A$57:$A$61,0))>=MAX(1.5,INDEX(Tablas!$B$57:$B$61,MATCH($C$26,Tablas!$A$57:$A$61,0))/2),"CUMPLE","NO CUMPLE") -> CUMPLE | E34: NTC 1500 – sistemas de ventilación
B36: Cajas de inspección: en cada cambio de dirección, unión de colectores y a distancias ≤ 15 m (criterio usual); dimensiones internas mínimas 0,60 × 0,60 m, con cañuela y tapa hermética. Sifón en todo aparato; tubería de ventilación prolongada ≥ 0,30 m sobre cubierta.

Sheet Aguas_Lluvias
A1: MEMORIA DE CÁLCULO – INSTALACIONES SANITARIAS, AGUAS LLUVIAS Y SISTEMA DE TRATAMIENTO IN SITU
A2: DRENAJE DE AGUAS LLUVIAS – MÉTODO RACIONAL
A3: Proyecto: Vivienda campestre unifamiliar – Restrepo (Valle del Cauca) | Rev. 0 | PENDIENTE: ajustar con planos arquitectónicos (D:\trabajo\proyecto\en curso\casa Restrepo)
B5: Las aguas lluvias se conducen por red independiente y NO deben ingresar al sistema séptico. Disposición propuesta: cuneta / zona verde de infiltración o almacenamiento para riego (PENDIENTE definir con planos y topografía).
A7: 1. INTENSIDAD DE DISEÑO – CURVA IDF REGIONAL (VARGAS Y DÍAZ-GRANADOS, 1998 – REGIÓN ANDINA)
A8: Ítem | B8: Descripción | C8: Símbolo | D8: Valor | E8: Unidad | F8: Referencia normativa / criterio / observación
A9: 1.1 | B9: Coeficiente a | C9: a | D9: 0.94 | F9: Región Andina (R1)
A10: 1.2 | B10: Coeficiente b | C10: b | D10: 0.18 | F10: Región Andina (R1)
A11: 1.3 | B11: Coeficiente c | C11: c | D11: 0.66 | F11: Región Andina (R1)
A12: 1.4 | B12: Coeficiente d | C12: d | D12: 0.83 | F12: Región Andina (R1)
A13: 1.5 | B13: Precipitación máxima promedio anual en 24 h | C13: M | D13: 75 | E13: mm | F13: PENDIENTE: estación IDEAM / CVC más cercana
A14: 1.6 | B14: Período de retorno | C14: Tr | D14: 10 | E14: años | F14: Criterio para drenaje de edificaciones (≥ 5 años)
A15: 1.7 | B15: Tiempo de concentración | C15: tc | D15: 10 | E15: min | F15: Cubiertas y patios pequeños (5–10 min)
A16: 1.8 | B16: Intensidad i = a·Tr^b·M^d / (tc/60)^c | C16: i | D16: =$D$9*$D$14^$D$10*$D$13^$D$12/($D$15/60)^$D$11 -> 167.11234 | E16: mm/h
A17: 1.9 | B17: Intensidad mínima de diseño | C17: imín | D17: 100 | E17: mm/h | F17: Criterio del diseñador
A18: 1.10 | B18: Intensidad de diseño adoptada = MÁX(i; imín) | C18: id | D18: =MAX($D$16,$D$17) -> 167.11234 | E18: mm/h
A20: 2. CAUDALES DE ESCORRENTÍA – Q = C·i·A / 3.600
A21: Ítem | B21: Descripción | C21: Símbolo | D21: Valor | E21: Unidad | F21: Referencia normativa / criterio / observación
A22: 2.1 | B22: Coeficiente de escorrentía – cubierta | C22: Cc | D22: 0.95 | F22: RAS 2000 Tabla D.4.5 (cubiertas 0,75–0,95)
A23: 2.2 | B23: Caudal de cubierta | C23: Qc | D23: =$D$22*$D$18*Datos!$D$31/3600 -> 7.9378363 | E23: L/s | F23: Área de cubierta: hoja Datos
A24: 2.3 | B24: Coeficiente de escorrentía – patios / terrazas duras | C24: Cp | D24: 0.85 | F24: RAS 2000 Tabla D.4.5 (pavimentos 0,70–0,95)
A25: 2.4 | B25: Caudal de patios | C25: Qp | D25: =$D$24*$D$18*Datos!$D$32/3600 -> 1.5782832 | E25: L/s
A26: 2.5 | B26: Caudal total de aguas lluvias | C26: Qll | D26: =$D$23+$D$25 -> 9.5161195 | E26: L/s
A28: 3. CANALES DE CUBIERTA (SECCIÓN RECTANGULAR – MANNING)
A29: Ítem | B29: Descripción | C29: Símbolo | D29: Valor | E29: Unidad | F29: Referencia normativa / criterio / observación
A30: 3.1 | B30: Número de canales | C30: nc | D30: 2 | E30: und | F30: PENDIENTE: ajustar con planos arquitectónicos (D:\trabajo\proyecto\en curso\casa Restrepo)
A31: 3.2 | B31: Caudal por canal = Qc / nc | C31: qc | D31: =$D$23/$D$30 -> 3.9689181 | E31: L/s
A32: 3.3 | B32: Ancho del canal | C32: b | D32: 0.15 | E32: m
A33: 3.4 | B33: Altura del canal | C33: h | D33: 0.12 | E33: m
A34: 3.5 | B34: Lámina máxima de diseño (fracción de h) | C34: y/h | D34: 0.75 | F34: Borde libre ≥ 25 %
A35: 3.6 | B35: Coeficiente de Manning (lámina galvanizada / PVC) | C35: n | D35: 0.012
A36: 3.7 | B36: Pendiente del canal | C36: S | D36: 0.005 | E36: m/m | F36: 0,5 % mínimo recomendado
A37: 3.8 | B37: Área hidráulica = b·y | C37: A | D37: =$D$32*$D$33*$D$34 -> 0.0135 | E37: m²
A38: 3.9 | B38: Radio hidráulico = A / (b + 2y) | C38: R | D38: =$D$37/($D$32+2*$D$33*$D$34) -> 0.040909091 | E38: m
A39: 3.10 | B39: Capacidad = (1/n)·A·R^(2/3)·S^(1/2) | C39: Qcap | D39: =1000/$D$35*$D$37*$D$38^(2/3)*SQRT($D$36) -> 9.444611 | E39: L/s
A40: 3.11 | B40: Capacidad del canal ≥ caudal por canal | C40: ✓ | D40: =IF($D$39>=$D$31,"CUMPLE","NO CUMPLE") -> CUMPLE
A42: 4. BAJANTES DE AGUAS LLUVIAS
A43: Ítem | B43: Descripción | C43: Símbolo | D43: Valor | E43: Unidad | F43: Referencia normativa / criterio / observación
A44: 4.1 | B44: Número de bajantes | C44: nb | D44: 4 | E44: und | F44: PENDIENTE: ajustar con planos arquitectónicos (D:\trabajo\proyecto\en curso\casa Restrepo)
A45: 4.2 | B45: Diámetro de bajante | C45: Ø | D45: 3" | F45: Lista desplegable
...

Sheet Hidraulica_Colectores
A1: MEMORIA DE CÁLCULO – INSTALACIONES SANITARIAS, AGUAS LLUVIAS Y SISTEMA DE TRATAMIENTO IN SITU
A2: VERIFICACIÓN HIDRÁULICA DE COLECTORES – MANNING, TUBO PARCIALMENTE LLENO
A3: Proyecto: Vivienda campestre unifamiliar – Restrepo (Valle del Cauca) | Rev. 0 | PENDIENTE: ajustar con planos arquitectónicos (D:\trabajo\proyecto\en curso\casa Restrepo)
B5: Caudal de desagües sanitarios por curva de Hunter aplicada a las UD acumuladas; caudal pluvial por método racional.
A7: 1. PARÁMETROS DE DISEÑO
A8: Coeficiente de Manning PVC | C8: 0.009 | E8: RAS 2000 / Res. 0330/2017 – PVC n = 0,009
A9: Velocidad mínima | C9: 0.45 | D9: m/s | E9: RAS 2000 Título D (autolimpieza)
A10: Velocidad máxima | C10: 5 | D10: m/s | E10: RAS 2000 / Res. 0330/2017 (PVC)
A11: Esfuerzo cortante mínimo | C11: 1 | D11: Pa | E11: Res. 0330/2017 (autolimpieza)
A12: Relación y/D máxima | C12: 0.75 | E12: Criterio de diseño (Res. 0330/2017 admite hasta 0,85)
A14: 2. VERIFICACIÓN POR TRAMOS
A15: Tramo | B15: Descripción | C15: Q diseño (L/s) | D15: Ø nominal | E15: Ø interno (m) | F15: S (m/m) | G15: n | H15: Q tubo lleno (L/s) | I15: V tubo lleno (m/s) | J15: Q/Qo | K15: y/D | L15: V/Vo | M15: V real (m/s) | N15: R/Ro | O15: R (m) | P15: τ (Pa) | Q15: Verif. y/D | R15: Verif. V | S15: Verif. τ
A16: C1 | B16: Ramal cocina + BBQ → trampa de grasas | C16: =IF((UD_Desagues!$D$19)<=MIN(Tablas!$A$9:$A$44),INDEX(Tablas!$C$9:$C$44,1),IF((UD_Desagues!$D$19)>=MAX(Tablas!$A$9:$A$44),INDEX(Tablas!$C$9:$C$44,ROWS(Tablas!$A$9:$A$44)),INDEX(Tablas!$C$9:$C$44,MATCH((UD_Desagues!$D$19),Tablas!$A$9:$A$44,1))+((UD_Desagues!$D$19)-INDEX(Tablas!$A$9:$A$44,MATCH((UD_Desagues!$D$19),Tablas!$A$9:$A$44,1)))*(INDEX(Tablas!$C$9:$C$44,MATCH((UD_Desagues!$D$19),Tablas!$A$9:$A$44,1)+1)-INDEX(Tablas!$C$9:$C$44,MATCH((UD_Desagues!$D$19),Tablas!$A$9:$A$44,1)))/(INDEX(Tablas!$A$9:$A$44,MATCH((UD_Desagues!$D$19),Tablas!$A$9:$A$44,1)+1)-INDEX(Tablas!$A$9:$A$44,MATCH((UD_Desagues!$D$19),Tablas!$A$9:$A$44,1))))) -> 0.5047216 | D16: 2" | E16: =INDEX(Tablas!$E$57:$E$61,MATCH(D16,Tablas!$A$57:$A$61,0))/1000 -> 0.05672 | F16: 0.02 | G16: =$C$8 -> 0.009 | H16: =1000/G16*(PI()*E16^2/4)*(E16/4)^(2/3)*SQRT(F16) -> 2.3260496 | I16: =H16/1000/(PI()*E16^2/4) -> 0.92056963 | J16: =C16/H16 -> 0.2169866 | K16: =IF(J16>MAX(Tablas!$G$117:$G$206),1,IF((J16)<=MIN(Tablas!$G$117:$G$206),INDEX(Tablas!$A$117:$A$206,1),IF((J16)>=MAX(Tablas!$G$117:$G$206),INDEX(Tablas!$A$117:$A$206,ROWS(Tablas!$G$117:$G$206)),INDEX(Tablas!$A$117:$A$206,MATCH((J16),Tablas!$G$117:$G$206,1))+((J16)-INDEX(Tablas!$G$117:$G$206,MATCH((J16),Tablas!$G$117:$G$206,1)))*(INDEX(Tablas!$A$117:$A$206,MATCH((J16),Tablas!$G$117:$G$206,1)+1)-INDEX(Tablas!$A$117:$A$206,MATCH((J16),Tablas!$G$117:$G$206,1)))/(INDEX(Tablas!$G$117:$G$206,MATCH((J16),Tablas!$G$117:$G$206,1)+1)-INDEX(Tablas!$G$117:$G$206,MATCH((J16),Tablas!$G$117:$G$206,1)))))) -> 0.31636647 | L16: =IF((K16)<=MIN(Tablas!$A$117:$A$206),INDEX(Tablas!$F$117:$F$206,1),IF((K16)>=MAX(Tablas!$A$117:$A$206),INDEX(Tablas!$F$117:$F$206,ROWS(Tablas!$A$117:$A$206)),INDEX(Tablas!$F$117:$F$206,MATCH((K16),Tablas!$A$117:$A$206,1))+((K16)-INDEX(Tablas!$A$117:$A$206,MATCH((K16),Tablas!$A$117:$A$206,1)))*(INDEX(Tablas!$F$117:$F$206,MATCH((K16),Tablas!$A$117:$A$206,1)+1)-INDEX(Tablas!$F$117:$F$206,MATCH((K16),Tablas!$A$117:$A$206,1)))/(INDEX(Tablas!$A$117:$A$206,MATCH((K16),Tablas!$A$117:$A$206,1)+1)-INDEX(Tablas!$A$117:$A$206,MATCH((K16),Tablas!$A$117:$A$206,1))))) -> 0.79886924 | M16: =L16*I16 -> 0.73541476 | N16: =IF((K16)<=MIN(Tablas!$A$117:$A$206),INDEX(Tablas!$E$117:$E$206,1),IF((K16)>=MAX(Tablas!$A$117:$A$206),INDEX(Tablas!$E$117:$E$206,ROWS(Tablas!$A$117:$A$206)),INDEX(Tablas!$E$117:$E$206,MATCH((K16),Tablas!$A$117:$A$206,1))+((K16)-INDEX(Tablas!$A$117:$A$206,MATCH((K16),Tablas!$A$117:$A$206,1)))*(INDEX(Tablas!$E$117:$E$206,MATCH((K16),Tablas!$A$117:$A$206,1)+1)-INDEX(Tablas!$E$117:$E$206,MATCH((K16),Tablas!$A$117:$A$206,1)))/(INDEX(Tablas!$A$117:$A$206,MATCH((K16),Tablas!$A$117:$A$206,1)+1)-INDEX(Tablas!$A$117:$A$206,MATCH((K16),Tablas!$A$117:$A$206,1))))) -> 0.71404341 | O16: =N16*E16/4 -> 0.010125136 | P16: =9810*O16*F16 -> 1.9865516 | Q16: =IF(K16<=$C$12,"CUMPLE","NO CUMPLE") -> CUMPLE | R16: =IF(AND(M16>=$C$9,M16<=$C$10),"CUMPLE","NO CUMPLE") -> CUMPLE | S16: =IF(P16>=$C$11,"CUMPLE","NO CUMPLE") -> CUMPLE
A17: C2 | B17: Colector principal → tanque séptico | C17: =IF((UD_Desagues!$D$18)<=MIN(Tablas!$A$9:$A$44),INDEX(Tablas!$C$9:$C$44,1),IF((UD_Desagues!$D$18)>=MAX(Tablas!$A$9:$A$44),INDEX(Tablas!$C$9:$C$44,ROWS(Tablas!$A$9:$A$44)),INDEX(Tablas!$C$9:$C$44,MATCH((UD_Desagues!$D$18),Tablas!$A$9:$A$44,1))+((UD_Desagues!$D$18)-INDEX(Tablas!$A$9:$A$44,MATCH((UD_Desagues!$D$18),Tablas!$A$9:$A$44,1)))*(INDEX(Tablas!$C$9:$C$44,MATCH((UD_Desagues!$D$18),Tablas!$A$9:$A$44,1)+1)-INDEX(Tablas!$C$9:$C$44,MATCH((UD_Desagues!$D$18),Tablas!$A$9:$A$44,1)))/(INDEX(Tablas!$A$9:$A$44,MATCH((UD_Desagues!$D$18),Tablas!$A$9:$A$44,1)+1)-INDEX(Tablas!$A$9:$A$44,MATCH((UD_Desagues!$D$18),Tablas!$A$9:$A$44,1))))) -> 1.5507571 | D17: 4" | E17: =INDEX(Tablas!$E$57:$E$61,MATCH(D17,Tablas!$A$57:$A$61,0))/1000 -> 0.1095 | F17: 0.02 | G17: =$C$8 -> 0.009 | H17: =1000/G17*(PI()*E17^2/4)*(E17/4)^(2/3)*SQRT(F17) -> 13.440849 | I17: =H17/1000/(PI()*E17^2/4) -> 1.427278 | J17: =C17/H17 -> 0.11537643 | K17: =IF(J17>MAX(Tablas!$G$117:$G$206),1,IF((J17)<=MIN(Tablas!$G$117:$G$206),INDEX(Tablas!$A$117:$A$206,1),IF((J17)>=MAX(Tablas!$G$117:$G$206),INDEX(Tablas!$A$117:$A$206,ROWS(Tablas!$G$117:$G$206)),INDEX(Tablas!$A$117:$A$206,MATCH((J17),Tablas!$G$117:$G$206,1))+((J17)-INDEX(Tablas!$G$117:$G$206,MATCH((J17),Tablas!$G$117:$G$206,1)))*(INDEX(Tablas!$A$117:$A$206,MATCH((J17),Tablas!$G$117:$G$206,1)+1)-INDEX(Tablas!$A$117:$A$206,MATCH((J17),Tablas!$G$117:$G$206,1)))/(INDEX(Tablas!$G$117:$G$206,MATCH((J17),Tablas!$G$117:$G$206,1)+1)-INDEX(Tablas!$G$117:$G$206,MATCH((J17),Tablas!$G$117:$G$206,1)))))) -> 0.22934509 | L17: =IF((K17)<=MIN(Tablas!$A$117:$A$206),INDEX(Tablas!$F$117:$F$206,1),IF((K17)>=MAX(Tablas!$A$117:$A$206),INDEX(Tablas!$F$117:$F$206,ROWS(Tablas!$A$117:$A$206)),INDEX(Tablas!$F$117:$F$206,MATCH((K17),Tablas!$A$117:$A$206,1))+((K17)-INDEX(Tablas!$A$117:$A$206,MATCH((K17),Tablas!$A$117:$A$206,1)))*(INDEX(Tablas!$F$117:$F$206,MATCH((K17),Tablas!$A$117:$A$206,1)+1)-INDEX(Tablas!$F$117:$F$206,MATCH((K17),Tablas!$A$117:$A$206,1)))/(INDEX(Tablas!$A$117:$A$206,MATCH((K17),Tablas!$A$117:$A$206,1)+1)-INDEX(Tablas!$A$117:$A$206,MATCH((K17),Tablas!$A$117:$A$206,1))))) -> 0.66663456 | M17: =L17*I17 -> 0.95147285 | N17: =IF((K17)<=MIN(Tablas!$A$117:$A$206),INDEX(Tablas!$E$117:$E$206,1),IF((K17)>=MAX(Tablas!$A$117:$A$206),INDEX(Tablas!$E$117:$E$206,ROWS(Tablas!$A$117:$A$206)),INDEX(Tablas!$E$117:$E$206,MATCH((K17),Tablas!$A$117:$A$206,1))+((K17)-INDEX(Tablas!$A$117:$A$206,MATCH((K17),Tablas!$A$117:$A$206,1)))*(INDEX(Tablas!$E$117:$E$206,MATCH((K17),Tablas!$A$117:$A$206,1)+1)-INDEX(Tablas!$E$117:$E$206,MATCH((K17),Tablas!$A$117:$A$206,1)))/(INDEX(Tablas!$A$117:$A$206,MATCH((K17),Tablas!$A$117:$A$206,1)+1)-INDEX(Tablas!$A$117:$A$206,MATCH((K17),Tablas!$A$117:$A$206,1))))) -> 0.54429999 | O17: =N17*E17/4 -> 0.014900212 | P17: =9810*O17*F17 -> 2.9234216 | Q17: =IF(K17<=$C$12,"CUMPLE","NO CUMPLE") -> CUMPLE | R17: =IF(AND(M17>=$C$9,M17<=$C$10),"CUMPLE","NO CUMPLE") -> CUMPLE | S17: =IF(P17>=$C$11,"CUMPLE","NO CUMPLE") -> CUMPLE
A18: C3 | B18: Tanque séptico → FAFA → campo de infiltración | C18: =IF((UD_Desagues!$D$18)<=MIN(Tablas!$A$9:$A$44),INDEX(Tablas!$C$9:$C$44,1),IF((UD_Desagues!$D$18)>=MAX(Tablas!$A$9:$A$44),INDEX(Tablas!$C$9:$C$44,ROWS(Tablas!$A$9:$A$44)),INDEX(Tablas!$C$9:$C$44,MATCH((UD_Desagues!$D$18),Tablas!$A$9:$A$44,1))+((UD_Desagues!$D$18)-INDEX(Tablas!$A$9:$A$44,MATCH((UD_Desagues!$D$18),Tablas!$A$9:$A$44,1)))*(INDEX(Tablas!$C$9:$C$44,MATCH((UD_Desagues!$D$18),Tablas!$A$9:$A$44,1)+1)-INDEX(Tablas!$C$9:$C$44,MATCH((UD_Desagues!$D$18),Tablas!$A$9:$A$44,1)))/(INDEX(Tablas!$A$9:$A$44,MATCH((UD_Desagues!$D$18),Tablas!$A$9:$A$44,1)+1)-INDEX(Tablas!$A$9:$A$44,MATCH((UD_Desagues!$D$18),Tablas!$A$9:$A$44,1))))) -> 1.5507571 | D18: 4" | E18: =INDEX(Tablas!$E$57:$E$61,MATCH(D18,Tablas!$A$57:$A$61,0))/1000 -> 0.1095 | F18: 0.01 | G18: =$C$8 -> 0.009 | H18: =1000/G18*(PI()*E18^2/4)*(E18/4)^(2/3)*SQRT(F18) -> 9.5041153 | I18: =H18/1000/(PI()*E18^2/4) -> 1.009238 | J18: =C18/H18 -> 0.16316691 | K18: =IF(J18>MAX(Tablas!$G$117:$G$206),1,IF((J18)<=MIN(Tablas!$G$117:$G$206),INDEX(Tablas!$A$117:$A$206,1),IF((J18)>=MAX(Tablas!$G$117:$G$206),INDEX(Tablas!$A$117:$A$206,ROWS(Tablas!$G$117:$G$206)),INDEX(Tablas!$A$117:$A$206,MATCH((J18),Tablas!$G$117:$G$206,1))+((J18)-INDEX(Tablas!$G$117:$G$206,MATCH((J18),Tablas!$G$117:$G$206,1)))*(INDEX(Tablas!$A$117:$A$206,MATCH((J18),Tablas!$G$117:$G$206,1)+1)-INDEX(Tablas!$A$117:$A$206,MATCH((J18),Tablas!$G$117:$G$206,1)))/(INDEX(Tablas!$G$117:$G$206,MATCH((J18),Tablas!$G$117:$G$206,1)+1)-INDEX(Tablas!$G$117:$G$206,MATCH((J18),Tablas!$G$117:$G$206,1)))))) -> 0.27315413 | L18: =IF((K18)<=MIN(Tablas!$A$117:$A$206),INDEX(Tablas!$F$117:$F$206,1),IF((K18)>=MAX(Tablas!$A$117:$A$206),INDEX(Tablas!$F$117:$F$206,ROWS(Tablas!$A$117:$A$206)),INDEX(Tablas!$F$117:$F$206,MATCH((K18),Tablas!$A$117:$A$206,1))+((K18)-INDEX(Tablas!$A$117:$A$206,MATCH((K18),Tablas!$A$117:$A$206,1)))*(INDEX(Tablas!$F$117:$F$206,MATCH((K18),Tablas!$A$117:$A$206,1)+1)-INDEX(Tablas!$F$117:$F$206,MATCH((K18),Tablas!$A$117:$A$206,1)))/(INDEX(Tablas!$A$117:$A$206,MATCH((K18),Tablas!$A$117:$A$206,1)+1)-INDEX(Tablas!$A$117:$A$206,MATCH((K18),Tablas!$A$117:$A$206,1))))) -> 0.7367297 | M18: =L18*I18 -> 0.74353558 | N18: =IF((K18)<=MIN(Tablas!$A$117:$A$206),INDEX(Tablas!$E$117:$E$206,1),IF((K18)>=MAX(Tablas!$A$117:$A$206),INDEX(Tablas!$E$117:$E$206,ROWS(Tablas!$A$117:$A$206)),INDEX(Tablas!$E$117:$E$206,MATCH((K18),Tablas!$A$117:$A$206,1))+((K18)-INDEX(Tablas!$A$117:$A$206,MATCH((K18),Tablas!$A$117:$A$206,1)))*(INDEX(Tablas!$E$117:$E$206,MATCH((K18),Tablas!$A$117:$A$206,1)+1)-INDEX(Tablas!$E$117:$E$206,MATCH((K18),Tablas!$A$117:$A$206,1)))/(INDEX(Tablas!$A$117:$A$206,MATCH((K18),Tablas!$A$117:$A$206,1)+1)-INDEX(Tablas!$A$117:$A$206,MATCH((K18),Tablas!$A$117:$A$206,1))))) -> 0.63237834 | O18: =N18*E18/4 -> 0.017311357 | P18: =9810*O18*F18 -> 1.6982441 | Q18: =IF(K18<=$C$12,"CUMPLE","NO CUMPLE") -> CUMPLE | R18: =IF(AND(M18>=$C$9,M18<=$C$10),"CUMPLE","NO CUMPLE") -> CUMPLE | S18: =IF(P18>=$C$11,"CUMPLE","NO CUMPLE") -> CUMPLE
A19: C4 | B19: Colector pluvial → disposición | C19: =Aguas_Lluvias!$D$26 -> 9.5161195 | D19: 6" | E19: =INDEX(Tablas!$E$57:$E$61,MATCH(D19,Tablas!$A$57:$A$61,0))/1000 -> 0.16168 | F19: 0.01 | G19: =$C$8 -> 0.009 | H19: =1000/G19*(PI()*E19^2/4)*(E19/4)^(2/3)*SQRT(F19) -> 26.86731 | I19: =H19/1000/(PI()*E19^2/4) -> 1.3086445 | J19: =C19/H19 -> 0.35418952 | K19: =IF(J19>MAX(Tablas!$G$117:$G$206),1,IF((J19)<=MIN(Tablas!$G$117:$G$206),INDEX(Tablas!$A$117:$A$206,1),IF((J19)>=MAX(Tablas!$G$117:$G$206),INDEX(Tablas!$A$117:$A$206,ROWS(Tablas!$G$117:$G$206)),INDEX(Tablas!$A$117:$A$206,MATCH((J19),Tablas!$G$117:$G$206,1))+((J19)-INDEX(Tablas!$G$117:$G$206,MATCH((J19),Tablas!$G$117:$G$206,1)))*(INDEX(Tablas!$A$117:$A$206,MATCH((J19),Tablas!$G$117:$G$206,1)+1)-INDEX(Tablas!$A$117:$A$206,MATCH((J19),Tablas!$G$117:$G$206,1)))/(INDEX(Tablas!$G$117:$G$206,MATCH((J19),Tablas!$G$117:$G$206,1)+1)-INDEX(Tablas!$G$117:$G$206,MATCH((J19),Tablas!$G$117:$G$206,1)))))) -> 0.41107123 | L19: =IF((K19)<=MIN(Tablas!$A$117:$A$206),INDEX(Tablas!$F$117:$F$206,1),IF((K19)>=MAX(Tablas!$A$117:$A$206),INDEX(Tablas!$F$117:$F$206,ROWS(Tablas!$A$117:$A$206)),INDEX(Tablas!$F$117:$F$206,MATCH((K19),Tablas!$A$117:$A$206,1))+((K19)-INDEX(Tablas!$A$117:$A$206,MATCH((K19),Tablas!$A$117:$A$206,1)))*(INDEX(Tablas!$F$117:$F$206,MATCH((K19),Tablas!$A$117:$A$206,1)+1)-INDEX(Tablas!$F$117:$F$206,MATCH((K19),Tablas!$A$117:$A$206,1)))/(INDEX(Tablas!$A$117:$A$206,MATCH((K19),Tablas!$A$117:$A$206,1)+1)-INDEX(Tablas!$A$117:$A$206,MATCH((K19),Tablas!$A$117:$A$206,1))))) -> 0.91430082 | M19: =L19*I19 -> 1.1964948 | N19: =IF((K19)<=MIN(Tablas!$A$117:$A$206),INDEX(Tablas!$E$117:$E$206,1),IF((K19)>=MAX(Tablas!$A$117:$A$206),INDEX(Tablas!$E$117:$E$206,ROWS(Tablas!$A$117:$A$206)),INDEX(Tablas!$E$117:$E$206,MATCH((K19),Tablas!$A$117:$A$206,1))+((K19)-INDEX(Tablas!$A$117:$A$206,MATCH((K19),Tablas!$A$117:$A$206,1)))*(INDEX(Tablas!$E$117:$E$206,MATCH((K19),Tablas!$A$117:$A$206,1)+1)-INDEX(Tablas!$E$117:$E$206,MATCH((K19),Tablas!$A$117:$A$206,1)))/(INDEX(Tablas!$A$117:$A$206,MATCH((K19),Tablas!$A$117:$A$206,1)+1)-INDEX(Tablas!$A$117:$A$206,MATCH((K19),Tablas!$A$117:$A$206,1))))) -> 0.87425032 | O19: =N19*E19/4 -> 0.035337198 | P19: =9810*O19*F19 -> 3.4665791 | Q19: =IF(K19<=$C$12,"CUMPLE","NO CUMPLE") -> CUMPLE | R19: =IF(AND(M19>=$C$9,M19<=$C$10),"CUMPLE","NO CUMPLE") -> CUMPLE | S19: =IF(P19>=$C$11,"CUMPLE","NO CUMPLE") -> CUMPLE
A21: Relación y/D ≤ máxima en todos los colectores | C21: =IF(COUNTIF(Q16:Q19,"NO CUMPLE")=0,"CUMPLE","NO CUMPLE") -> CUMPLE
A22: Velocidad entre Vmín y Vmáx en todos los colectores | C22: =IF(COUNTIF(R16:R19,"NO CUMPLE")=0,"CUMPLE","NO CUMPLE") -> CUMPLE
A23: Esfuerzo cortante ≥ τmín en todos los colectores | C23: =IF(COUNTIF(S16:S19,"NO CUMPLE")=0,"CUMPLE","NO CUMPLE") -> CUMPLE
B25: Qo = (1/n)·A·R^(2/3)·S^(1/2) a tubo lleno; y/D, V/Vo y R/Ro por interpolación en la tabla de relaciones hidráulicas (hoja Tablas); τ = γ·R·S con γ = 9.810 N/m³.

Sheet Trampa_Grasas
A1: MEMORIA DE CÁLCULO – INSTALACIONES SANITARIAS, AGUAS LLUVIAS Y SISTEMA DE TRATAMIENTO IN SITU
A2: TRAMPA DE GRASAS (RAS 2000 TÍTULO E – SISTEMAS IN SITU)
A3: Proyecto: Vivienda campestre unifamiliar – Restrepo (Valle del Cauca) | Rev. 0 | PENDIENTE: ajustar con planos arquitectónicos (D:\trabajo\proyecto\en curso\casa Restrepo)
A6: 1. CAUDAL DE DISEÑO
A7: Ítem | B7: Descripción | C7: Símbolo | D7: Valor | E7: Unidad | F7: Referencia normativa / criterio / observación
A8: 1.1 | B8: Aparatos conectados (lavaplatos cocina + BBQ) | C8: na | D8: =Datos!$D$26+Datos!$D$28 -> 2 | E8: und | F8: Hoja Datos
A9: 1.2 | B9: Caudal unitario de descarga por lavaplatos | C9: qa | D9: 0.25 | E9: L/s | F9: Criterio usual (lavaplatos doméstico)
A10: 1.3 | B10: Caudal de diseño = na × qa | C10: Qtg | D10: =$D$8*$D$9 -> 0.5 | E10: L/s
A12: 2. VOLUMEN
A13: Ítem | B13: Descripción | C13: Símbolo | D13: Valor | E13: Unidad | F13: Referencia normativa / criterio / observación
A14: 2.1 | B14: Tiempo de retención hidráulico | C14: TRH | D14: =IF($D$10<10,3,IF($D$10<20,4,5)) -> 3 | E14: min | F14: RAS 2000 Título E: 2–9 L/s: 3 min; 10–19 L/s: 4 min; ≥ 20 L/s: 5 min (se adopta 3 min como mínimo)
A15: 2.2 | B15: Volumen hidráulico = Qtg × TRH | C15: Vh | D15: =$D$10*$D$14*60 -> 90 | E15: L
A16: 2.3 | B16: Capacidad mínima adoptada (acumulación de grasas entre limpiezas) | C16: Vmín | D16: 150 | E16: L | F16: Criterio de diseño para vivienda
A17: 2.4 | B17: Volumen de diseño = MÁX(Vh; Vmín) | C17: Vtg | D17: =MAX($D$15,$D$16) -> 150 | E17: L
A19: 3. DIMENSIONES
A20: Ítem | B20: Descripción | C20: Símbolo | D20: Valor | E20: Unidad | F20: Referencia normativa / criterio / observación
A21: 3.1 | B21: Ancho útil | C21: B | D21: 0.4 | E21: m
A22: 3.2 | B22: Largo útil | C22: L | D22: 0.8 | E22: m
A23: 3.3 | B23: Profundidad útil | C23: h | D23: 0.5 | E23: m | F23: Más borde libre ≥ 0,30 m
A24: 3.4 | B24: Volumen útil construido = B·L·h | C24: Vc | D24: =$D$21*$D$22*$D$23*1000 -> 160 | E24: L
A25: 3.5 | B25: Volumen construido ≥ volumen de diseño | C25: ✓ | D25: =IF($D$24>=$D$17,"CUMPLE","NO CUMPLE") -> CUMPLE
A26: 3.6 | B26: Área superficial = B·L | C26: A | D26: =$D$21*$D$22 -> 0.32 | E26: m²
A27: 3.7 | B27: Área superficial ≥ 0,25 m² por cada L/s | C27: ✓ | D27: =IF($D$26>=0.25*$D$10,"CUMPLE","NO CUMPLE") -> CUMPLE | F27: RAS 2000 Título E – trampas de grasa
A28: 3.8 | B28: Velocidad ascendente = Qtg / A | C28: va | D28: =$D$10/1000/$D$26*1000 -> 1.5625 | E28: mm/s
A29: 3.9 | B29: Velocidad ascendente ≤ 4 mm/s | C29: ✓ | D29: =IF($D$28<=4,"CUMPLE","NO CUMPLE") -> CUMPLE | F29: RAS 2000 Título E – trampas de grasa
B30: Entrada por codo/tee sumergido y salida por tee con extremo inferior a ≥ 0,15 m del fondo; tapa removible para limpieza; limpieza periódica (mensual) y disposición de grasas con gestor autorizado.

Sheet Tanque_Septico
A1: MEMORIA DE CÁLCULO – INSTALACIONES SANITARIAS, AGUAS LLUVIAS Y SISTEMA DE TRATAMIENTO IN SITU
A2: TANQUE SÉPTICO (RAS 2000 TÍTULO E / NBR 7229)
A3: Proyecto: Vivienda campestre unifamiliar – Restrepo (Valle del Cauca) | Rev. 0 | PENDIENTE: ajustar con planos arquitectónicos (D:\trabajo\proyecto\en curso\casa Restrepo)
A6: 1. PARÁMETROS
A7: Ítem | B7: Descripción | C7: Símbolo | D7: Valor | E7: Unidad | F7: Referencia normativa / criterio / observación
A8: 1.1 | B8: Contribución diaria | C8: Cd | D8: =Caudales_AR!$D$27 -> 1530 | E8: L/d | F8: Hoja Caudales_AR
A9: 1.2 | B9: Período de retención T = f(Cd) | C9: T | D9: =INDEX(Tablas!$B$82:$B$88,MATCH($D$8,Tablas!$A$82:$A$88,1)) -> 0.92 | E9: d | F9: NBR 7229 Tabla 2 (hoja Tablas)
A10: 1.3 | B10: Intervalo de limpieza | C10: nl | D10: 2 | E10: años | F10: Entre 1 y 5 años
A11: 1.4 | B11: Intervalo de limpieza entero entre 1 y 5 años | C11: ✓ | D11: =IF(AND($D$10>=1,$D$10<=5,$D$10=INT($D$10)),"CUMPLE","NO CUMPLE") -> CUMPLE | F11: NBR 7229 Tabla 3
A12: 1.5 | B12: Rango de temperatura (1: ≤10 °C; 2: 10–20 °C; 3: >20 °C) | D12: =IF(Datos!$D$14<=10,1,IF(Datos!$D$14<=20,2,3)) -> 2 | F12: T media: hoja Datos
A13: 1.6 | B13: Tasa de acumulación de lodo digerido K | C13: K | D13: =CHOOSE($D$12,INDEX(Tablas!$B$92:$B$96,$D$10),INDEX(Tablas!$C$92:$C$96,$D$10),INDEX(Tablas!$D$92:$D$96,$D$10)) -> 105 | E13: d | F13: NBR 7229 Tabla 3
A14: 1.7 | B14: Contribución de lodo fresco ΣN·Lf | C14: ΣLf | D14: =Caudales_AR!$D$28 -> 11.4 | E14: L/d | F14: Hoja Caudales_AR
A16: 2. VOLUMEN ÚTIL
A17: Ítem | B17: Descripción | C17: Símbolo | D17: Valor | E17: Unidad | F17: Referencia normativa / criterio / observación
A18: 2.1 | B18: V = 1.000 + Cd·T + K·ΣN·Lf | C18: V | D18: =1000+$D$8*$D$9+$D$13*$D$14 -> 3604.6 | E18: L | F18: RAS 2000 Título E (fórmula NBR 7229)
A19: 2.2 | B19: Volumen útil | C19: V | D19: =$D$18/1000 -> 3.6046 | E19: m³
A21: 3. GEOMETRÍA (DOS CÁMARAS EN SERIE)
A22: Ítem | B22: Descripción | C22: Símbolo | D22: Valor | E22: Unidad | F22: Referencia normativa / criterio / observación
A23: 3.1 | B23: Profundidad útil | C23: h | D23: 1.5 | E23: m
A24: 3.2 | B24: Profundidad útil mínima | C24: hmín | D24: =INDEX(Tablas!$B$100:$B$102,MATCH($D$19,Tablas!$A$100:$A$102,1)) -> 1.2 | E24: m | F24: NBR 7229 Tabla 4
A25: 3.3 | B25: Profundidad útil máxima | C25: hmáx | D25: =INDEX(Tablas!$C$100:$C$102,MATCH($D$19,Tablas!$A$100:$A$102,1)) -> 2.2 | E25: m | F25: NBR 7229 Tabla 4
A26: 3.4 | B26: Profundidad útil dentro del rango | C26: ✓ | D26: =IF(AND($D$23>=$D$24,$D$23<=$D$25),"CUMPLE","NO CUMPLE") -> CUMPLE | F26: NBR 7229 Tabla 4
A27: 3.5 | B27: Ancho interno | C27: B | D27: 1.1 | E27: m
A28: 3.6 | B28: Ancho interno ≥ 0,80 m | C28: ✓ | D28: =IF($D$27>=0.8,"CUMPLE","NO CUMPLE") -> CUMPLE | F28: NBR 7229
A29: 3.7 | B29: Largo requerido = V / (h·B) | C29: Lreq | D29: =$D$19/($D$23*$D$27) -> 2.1846061 | E29: m
A30: 3.8 | B30: Largo interno adoptado | C30: L | D30: 2.3 | E30: m
A31: 3.9 | B31: Relación L / B | C31: L/B | D31: =$D$30/$D$27 -> 2.0909091
A32: 3.10 | B32: Relación L/B entre 2:1 y 4:1 | C32: ✓ | D32: =IF(AND($D$31>=2,$D$31<=4),"CUMPLE","NO CUMPLE") -> CUMPLE | F32: RAS 2000 Título E / NBR 7229
A33: 3.11 | B33: Volumen útil construido = h·B·L | C33: Vc | D33: =$D$23*$D$27*$D$30 -> 3.795 | E33: m³
A34: 3.12 | B34: Volumen construido ≥ volumen útil requerido | C34: ✓ | D34: =IF($D$33>=$D$19,"CUMPLE","NO CUMPLE") -> CUMPLE
A35: 3.13 | B35: Largo cámara 1 (2/3 L) | C35: L1 | D35: =2/3*$D$30 -> 1.5333333 | E35: m
A36: 3.14 | B36: Largo cámara 2 (1/3 L) | C36: L2 | D36: =1/3*$D$30 -> 0.76666667 | E36: m
A37: 3.15 | B37: Borde libre | C37: bl | D37: 0.3 | E37: m
A38: 3.16 | B38: Altura interna total = h + bl | C38: Ht | D38: =$D$23+$D$37 -> 1.8 | E38: m
B39: Entrada con tee a 0,05 m sobre la salida; dispositivos de entrada y salida con inmersión ≈ 1/3 h; tabique con paso a 2/3 h; tapas de inspección sobre cada cámara; tubería de ventilación. Lodos retirados por gestor autorizado cada nl años (Decreto 1076/2015).

Sheet FAFA
A1: MEMORIA DE CÁLCULO – INSTALACIONES SANITARIAS, AGUAS LLUVIAS Y SISTEMA DE TRATAMIENTO IN SITU
A2: FILTRO ANAEROBIO DE FLUJO ASCENDENTE (FAFA) – NBR 13969 / RAS 2000 TÍTULO E
A3: Proyecto: Vivienda campestre unifamiliar – Restrepo (Valle del Cauca) | Rev. 0 | PENDIENTE: ajustar con planos arquitectónicos (D:\trabajo\proyecto\en curso\casa Restrepo)
A6: 1. VOLUMEN
A7: Ítem | B7: Descripción | C7: Símbolo | D7: Valor | E7: Unidad | F7: Referencia normativa / criterio / observación
A8: 1.1 | B8: Contribución diaria | C8: Cd | D8: =Caudales_AR!$D$27 -> 1530 | E8: L/d | F8: Hoja Caudales_AR
A9: 1.2 | B9: Rango de temperatura (1: <15 °C; 2: 15–25 °C; 3: >25 °C) | D9: =IF(Datos!$D$14<15,1,IF(Datos!$D$14<=25,2,3)) -> 2
A10: 1.3 | B10: Fila de contribución en tabla | D10: =MATCH($D$8,Tablas!$A$106:$A$112,1) -> 2
A11: 1.4 | B11: Tiempo de retención hidráulico T | C11: T | D11: =CHOOSE($D$9,INDEX(Tablas!$B$106:$B$112,$D$10),INDEX(Tablas!$C$106:$C$112,$D$10),INDEX(Tablas!$D$106:$D$112,$D$10)) -> 0.92 | E11: d | F11: NBR 13969 Tabla 4
A12: 1.5 | B12: Volumen útil calculado V = 1,6·Cd·T | C12: V | D12: =1.6*$D$8*$D$11 -> 2252.16 | E12: L | F12: NBR 13969
A13: 1.6 | B13: Volumen útil de diseño = MÁX(V; 1.000 L) | C13: Vd | D13: =MAX($D$12,1000) -> 2252.16 | E13: L | F13: Volumen mínimo 1.000 L (NBR 13969)
A15: 2. GEOMETRÍA
A16: Ítem | B16: Descripción | C16: Símbolo | D16: Valor | E16: Unidad | F16: Referencia normativa / criterio / observación
A17: 2.1 | B17: Altura del lecho filtrante | C17: hl | D17: 1.2 | E17: m | F17: NBR 13969: 1,20 m
A18: 2.2 | B18: Área en planta requerida = Vd / hl | C18: Areq | D18: =$D$13/1000/$D$17 -> 1.8768 | E18: m²
A19: 2.3 | B19: Ancho interno | C19: B | D19: 1.2 | E19: m
A20: 2.4 | B20: Largo interno adoptado | C20: L | D20: 1.6 | E20: m
A21: 2.5 | B21: Área construida = B·L | C21: Ac | D21: =$D$19*$D$20 -> 1.92 | E21: m²
A22: 2.6 | B22: Área construida ≥ área requerida | C22: ✓ | D22: =IF($D$21>=$D$18,"CUMPLE","NO CUMPLE") -> CUMPLE
A23: 2.7 | B23: Altura de fondo falso (cámara de distribución) | C23: hf | D23: 0.3 | E23: m | F23: NBR 13969 (≤ 0,60 m)
A24: 2.8 | B24: Lámina sobre el lecho + canaleta de recolección | C24: hs | D24: 0.3 | E24: m
A25: 2.9 | B25: Borde libre | C25: bl | D25: 0.3 | E25: m
A26: 2.10 | B26: Altura interna total | C26: Ht | D26: =$D$23+$D$17+$D$24+$D$25 -> 2.1 | E26: m
A27: 2.11 | B27: Carga hidráulica superficial = Cd / Ac | C27: qs | D27: =$D$8/1000/$D$21 -> 0.796875 | E27: m³/m²·d
B28: Lecho de grava o piedra triturada N.° 4 (4–7 cm) o anillos plásticos; fondo falso perforado (orificios Ø 2,5 cm cada 15 cm, área de orificios ≤ 5 % del fondo); recolección del efluente por canaleta o tubería perforada en la superficie.
A30: 3. EFICIENCIA ESPERADA DEL SISTEMA TS + FAFA (INFORMATIVO PARA PERMISO DE VERTIMIENTO CVC)
A31: Ítem | B31: Descripción | C31: Símbolo | D31: Valor | E31: Unidad | F31: Referencia normativa / criterio / observación
A32: 3.1 | B32: Remoción DBO5 – tanque séptico | C32: Ets | D32: 0.35 | E32: % | F32: RAS 2000 Título E: 30–50 %
A33: 3.2 | B33: Remoción SST – tanque séptico | C33: Ets | D33: 0.6 | E33: % | F33: RAS 2000 Título E: 50–70 %
A34: 3.3 | B34: Remoción DBO5 – FAFA | C34: Ef | D34: 0.7 | E34: % | F34: NBR 13969: 40–75 %
A35: 3.4 | B35: Remoción SST – FAFA | C35: Ef | D35: 0.7 | E35: % | F35: NBR 13969: 60–90 %
A36: 3.5 | B36: Remoción global DBO5 = 1 − (1 − Ets)(1 − Ef) | C36: E | D36: =1-(1-$D$32)*(1-$D$34) -> 0.805 | E36: %
A37: 3.6 | B37: Remoción global SST | C37: E | D37: =1-(1-$D$33)*(1-$D$35) -> 0.88 | E37: %
A38: 3.7 | B38: DBO5 efluente | C38: DBOe | D38: =Caudales_AR!$D$40*(1-$D$36) -> 75.196078 | E38: mg/L | F38: Afluente: hoja Caudales_AR
A39: 3.8 | B39: SST efluente | C39: SSTe | D39: =Caudales_AR!$D$41*(1-$D$37) -> 46.27451 | E39: mg/L
B40: Comparar con los parámetros y valores aplicables de la Res. 699/2021 (vertimientos de ARD tratadas al suelo) y con los requisitos del trámite de permiso de vertimientos ante la CVC (Decreto 1076/2015, incluye evaluación ambiental del vertimiento y plan de gestión del riesgo).

Sheet Campo_Infiltracion
A1: MEMORIA DE CÁLCULO – INSTALACIONES SANITARIAS, AGUAS LLUVIAS Y SISTEMA DE TRATAMIENTO IN SITU
A2: CAMPO DE INFILTRACIÓN (ZANJAS DE ABSORCIÓN)
A3: Proyecto: Vivienda campestre unifamiliar – Restrepo (Valle del Cauca) | Rev. 0 | PENDIENTE: ajustar con planos arquitectónicos (D:\trabajo\proyecto\en curso\casa Restrepo)
B5: PENDIENTE: ejecutar prueba de percolación en sitio (mín. 3 perforaciones a la profundidad de las zanjas) y verificar nivel freático en época húmeda.
A7: 1. CAPACIDAD DE ABSORCIÓN DEL SUELO
A8: Ítem | B8: Descripción | C8: Símbolo | D8: Valor | E8: Unidad | F8: Referencia normativa / criterio / observación
A9: 1.1 | B9: Caudal de efluente a infiltrar | C9: Q | D9: =Caudales_AR!$D$27 -> 1530 | E9: L/d | F9: Hoja Caudales_AR
A10: 1.2 | B10: Tasa de percolación medida (tiempo para descenso de 1 cm) | C10: tp | D10: 4 | E10: min/cm | F10: PENDIENTE ensayo de percolación
A11: 1.3 | B11: Tasa de percolación en min/pulgada | C11: tp | D11: =$D$10*2.54 -> 10.16 | E11: min/in
A12: 1.4 | B12: Suelo apto: 1 ≤ tp ≤ 60 min/in | C12: ✓ | D12: =IF(AND($D$11>=1,$D$11<=60),"CUMPLE","NO CUMPLE") -> CUMPLE | F12: USPHS (1967): > 60 min/in no apto; < 1 min/in riesgo de contaminación
A13: 1.5 | B13: Tasa de aplicación = 5 / √tp [gal/ft²·d] × 40,74 | C13: qa | D13: =5/SQRT($D$11)*40.74 -> 63.906374 | E13: L/m²·d | F13: USPHS Manual of Septic-Tank Practice (1967)
A14: 1.6 | B14: Área de absorción requerida = Q / qa | C14: Areq | D14: =$D$9/$D$13 -> 23.941274 | E14: m² | F14: Solo fondo de zanja (conservador)
A16: 2. ZANJAS
A17: Ítem | B17: Descripción | C17: Símbolo | D17: Valor | E17: Unidad | F17: Referencia normativa / criterio / observación
A18: 2.1 | B18: Ancho de zanja | C18: b | D18: 0.6 | E18: m | F18: 0,45–0,90 m
A19: 2.2 | B19: Ancho de zanja entre 0,45 y 0,90 m | C19: ✓ | D19: =IF(AND($D$18>=0.45,$D$18<=0.9),"CUMPLE","NO CUMPLE") -> CUMPLE | F19: RAS 2000 Título E
A20: 2.3 | B20: Longitud total requerida = Areq / b | C20: Lreq | D20: =$D$14/$D$18 -> 39.902123 | E20: m
A21: 2.4 | B21: Longitud máxima por zanja | C21: Lmáx | D21: 20 | E21: m | F21: RAS 2000 Título E: ≤ 30 m
A22: 2.5 | B22: Longitud máxima por zanja ≤ 30 m | C22: ✓ | D22: =IF($D$21<=30,"CUMPLE","NO CUMPLE") -> CUMPLE | F22: RAS 2000 Título E
A23: 2.6 | B23: Número de zanjas = REDONDEAR.MAS(Lreq / Lmáx) | C23: nz | D23: =ROUNDUP($D$20/$D$21,0) -> 2 | E23: und
A24: 2.7 | B24: Longitud adoptada por zanja (redondeada al m) | C24: Lz | D24: =ROUNDUP($D$20/$D$23,0) -> 20 | E24: m
A25: 2.8 | B25: Longitud total instalada = nz × Lz | C25: Linst | D25: =$D$23*$D$24 -> 40 | E25: m
A26: 2.9 | B26: Longitud instalada ≥ longitud requerida | C26: ✓ | D26: =IF($D$25>=$D$20,"CUMPLE","NO CUMPLE") -> CUMPLE
A27: 2.10 | B27: Separación entre ejes de zanjas | C27: sz | D27: 2 | E27: m | F27: ≥ 2,0 m (criterio RAS 2000 / USPHS)
A28: 2.11 | B28: Separación entre zanjas ≥ 2,0 m | C28: ✓ | D28: =IF($D$27>=2,"CUMPLE","NO CUMPLE") -> CUMPLE
A29: 2.12 | B29: Profundidad de zanja (fondo) | C29: pz | D29: 0.7 | E29: m | F29: 0,45–0,90 m
A30: 2.13 | B30: Profundidad de zanja entre 0,45 y 0,90 m | C30: ✓ | D30: =IF(AND($D$29>=0.45,$D$29<=0.9),"CUMPLE","NO CUMPLE") -> CUMPLE
A31: 2.14 | B31: Profundidad del nivel freático estacional máximo | C31: NF | D31: 2.5 | E31: m | F31: PENDIENTE: apique / sondeo
A32: 2.15 | B32: Separación fondo de zanja – nivel freático | C32: Δ | D32: =$D$31-$D$29 -> 1.8 | E32: m
A33: 2.16 | B33: Separación al nivel freático ≥ 1,20 m | C33: ✓ | D33: =IF($D$32>=1.2,"CUMPLE","NO CUMPLE") -> CUMPLE | F33: RAS 2000 Título E
A34: 2.17 | B34: Pendiente de tubería perforada de distribución (Ø 4") | C34: S | D34: 0.003 | E34: m/m | F34: 0,2 %–0,5 %
A35: 2.18 | B35: Pendiente de distribución entre 0,2 % y 0,5 % | C35: ✓ | D35: =IF(AND($D$34>=0.002,$D$34<=0.005),"CUMPLE","NO CUMPLE") -> CUMPLE
A37: 3. DISTANCIAS MÍNIMAS (VERIFICAR EN PLANO DE IMPLANTACIÓN)
A38: Ítem | B38: Descripción | C38: Símbolo | D38: Valor | E38: Unidad | F38: Referencia normativa / criterio / observación
A39: 3.1 | B39: Campo a cuerpo de agua / nacimiento / quebrada – distancia en proyecto | C39: d | D39: 40 | E39: m | F39: PENDIENTE: plano de implantación
A40: 3.2 | B40: Campo a cuerpo de agua / nacimiento / quebrada – distancia mínima | C40: dmín | D40: 30 | E40: m | F40: Ronda hídrica ≥ 30 m (Decreto 1076/2015; acotamiento CVC)
A41: 3.3 | B41: Campo a cuerpo de agua / nacimiento / quebrada ≥ distancia mínima | C41: ✓ | D41: =IF($D$39>=$D$40,"CUMPLE","NO CUMPLE") -> CUMPLE | F41: Ronda hídrica ≥ 30 m (Decreto 1076/2015; acotamiento CVC)
A42: 3.4 | B42: Campo a pozo o aljibe de abastecimiento – distancia en proyecto | C42: d | D42: 35 | E42: m | F42: PENDIENTE: plano de implantación
A43: 3.5 | B43: Campo a pozo o aljibe de abastecimiento – distancia mínima | C43: dmín | D43: 30 | E43: m | F43: Criterio de referencia RAS 2000 Título E
A44: 3.6 | B44: Campo a pozo o aljibe de abastecimiento ≥ distancia mínima | C44: ✓ | D44: =IF($D$42>=$D$43,"CUMPLE","NO CUMPLE") -> CUMPLE | F44: Criterio de referencia RAS 2000 Título E
...

Sheet Resumen
A1: MEMORIA DE CÁLCULO – INSTALACIONES SANITARIAS, AGUAS LLUVIAS Y SISTEMA DE TRATAMIENTO IN SITU
A2: RESUMEN DE RESULTADOS Y VERIFICACIONES
A3: Proyecto: Vivienda campestre unifamiliar – Restrepo (Valle del Cauca) | Rev. 0 | PENDIENTE: ajustar con planos arquitectónicos (D:\trabajo\proyecto\en curso\casa Restrepo)
A6: 1. RESULTADOS PRINCIPALES
A7: Ítem | B7: Descripción | C7: Símbolo | D7: Valor | E7: Unidad | F7: Referencia normativa / criterio / observación
A8: 1.1 | B8: Nivel de complejidad (RAS 2000) | D8: =Poblacion!$D$26 -> BAJO
A9: 1.2 | B9: Población con pernoctación (diseño) | D9: =Poblacion!$D$19 -> 11 | E9: hab
A10: 1.3 | B10: Población flotante diurna (empleados) | D10: =Poblacion!$D$20 -> 2 | E10: emp
A11: 1.4 | B11: Población total de diseño | D11: =Poblacion!$D$21 -> 13 | E11: hab
A12: 1.5 | B12: Dotación neta adoptada – residencial | D12: =Poblacion!$D$38 -> 130 | E12: L/hab·d
A13: 1.6 | B13: Consumo neto total | D13: =Poblacion!$E$47 -> 1530 | E13: L/d
A14: 1.7 | B14: Caudal medio diario de ARD | D14: =Caudales_AR!$D$12 -> 0.015052083 | E14: L/s
A15: 1.8 | B15: Contribución diaria al sistema in situ | D15: =Caudales_AR!$D$27 -> 1530 | E15: L/d
A16: 1.9 | B16: Unidades de descarga totales | D16: =UD_Desagues!$D$18 -> 34 | E16: UD
A17: 1.10 | B17: Intensidad de diseño de lluvia | D17: =Aguas_Lluvias!$D$18 -> 167.11234 | E17: mm/h
A18: 1.11 | B18: Caudal total de aguas lluvias | D18: =Aguas_Lluvias!$D$26 -> 9.5161195 | E18: L/s
A19: 1.12 | B19: Volumen de trampa de grasas | D19: =Trampa_Grasas!$D$17 -> 150 | E19: L
A20: 1.13 | B20: Volumen útil tanque séptico | D20: =Tanque_Septico!$D$19 -> 3.6046 | E20: m³
A21: 1.14 | B21: Largo interno tanque séptico (2 cámaras) | D21: =Tanque_Septico!$D$30 -> 2.3 | E21: m
A22: 1.15 | B22: Ancho interno tanque séptico | D22: =Tanque_Septico!$D$27 -> 1.1 | E22: m
A23: 1.16 | B23: Profundidad útil tanque séptico | D23: =Tanque_Septico!$D$23 -> 1.5 | E23: m
A24: 1.17 | B24: Volumen útil FAFA | D24: =FAFA!$D$13 -> 2252.16 | E24: L
A25: 1.18 | B25: Remoción global DBO5 (TS + FAFA) | D25: =FAFA!$D$36 -> 0.805 | E25: %
A26: 1.19 | B26: Tasa de aplicación del suelo | D26: =Campo_Infiltracion!$D$13 -> 63.906374 | E26: L/m²·d
A27: 1.20 | B27: Área de absorción requerida | D27: =Campo_Infiltracion!$D$14 -> 23.941274 | E27: m²
A28: 1.21 | B28: Número de zanjas | D28: =Campo_Infiltracion!$D$23 -> 2 | E28: und
A29: 1.22 | B29: Longitud por zanja | D29: =Campo_Infiltracion!$D$24 -> 20 | E29: m
A31: 2. VERIFICACIONES NORMATIVAS Y DE CRITERIO
A32: Ítem | B32: Verificación | C32: Hoja | D32: Resultado | F32: Observación
A33: 1 | B33: Dotación base dentro del rango RAS 2000 | C33: Poblacion | D33: =Poblacion!$D$34 -> CUMPLE
A34: 2 | B34: Contribución adoptada ≥ CR × dotación neta (diseño conservador) | C34: Caudales_AR | D34: =Caudales_AR!$D$30 -> CUMPLE
A35: 3 | B35: Capacidad del ramal de baño | C35: UD_Desagues | D35: =UD_Desagues!$F$23 -> CUMPLE
A36: 4 | B36: Capacidad del ramal de cocina | C36: UD_Desagues | D36: =UD_Desagues!$F$24 -> CUMPLE
A37: 5 | B37: Capacidad del ramal de ropas | C37: UD_Desagues | D37: =UD_Desagues!$F$25 -> CUMPLE
A38: 6 | B38: Capacidad de la bajante | C38: UD_Desagues | D38: =UD_Desagues!$F$26 -> CUMPLE
A39: 7 | B39: Capacidad del colector principal | C39: UD_Desagues | D39: =UD_Desagues!$F$27 -> CUMPLE
A40: 8 | B40: Ø de ramal/colector que recibe sanitarios ≥ 3" (se adopta 4") | C40: UD_Desagues | D40: =UD_Desagues!$D$31 -> CUMPLE
A41: 9 | B41: Pendiente del colector entre 1 % y 4 % | C41: UD_Desagues | D41: =UD_Desagues!$D$32 -> CUMPLE
A42: 10 | B42: Ventilación ≥ MÁX(1-1/2"; ½ Ø bajante/colector) | C42: UD_Desagues | D42: =UD_Desagues!$D$34 -> CUMPLE
A43: 11 | B43: Capacidad del canal ≥ caudal por canal | C43: Aguas_Lluvias | D43: =Aguas_Lluvias!$D$40 -> CUMPLE
...

Sheet Tablas
A1: MEMORIA DE CÁLCULO – INSTALACIONES SANITARIAS, AGUAS LLUVIAS Y SISTEMA DE TRATAMIENTO IN SITU
A2: TABLAS DE REFERENCIA
A3: Proyecto: Vivienda campestre unifamiliar – Restrepo (Valle del Cauca) | Rev. 0 | PENDIENTE: ajustar con planos arquitectónicos (D:\trabajo\proyecto\en curso\casa Restrepo)
A6: 1. CURVA DE HUNTER – GASTO PROBABLE (TANQUE)
B7: Hunter (1940). Fuente: IPC Tabla E103.3(3), aparatos con tanque. Conversión 1 gpm = 0,0631 L/s. Método de gastos probables aceptado por NTC 1500.
A8: Unidades (UC / UD) | B8: Q (gpm) | C8: Q (L/s)
A9: 1 | B9: 3 | C9: =B9*0.0630902 -> 0.1892706
A10: 2 | B10: 5 | C10: =B10*0.0630902 -> 0.315451
A11: 3 | B11: 6.5 | C11: =B11*0.0630902 -> 0.4100863
A12: 4 | B12: 8 | C12: =B12*0.0630902 -> 0.5047216
A13: 5 | B13: 9.4 | C13: =B13*0.0630902 -> 0.59304788
A14: 6 | B14: 10.7 | C14: =B14*0.0630902 -> 0.67506514
A15: 7 | B15: 11.8 | C15: =B15*0.0630902 -> 0.74446436
A16: 8 | B16: 12.8 | C16: =B16*0.0630902 -> 0.80755456
A17: 9 | B17: 13.7 | C17: =B17*0.0630902 -> 0.86433574
A18: 10 | B18: 14.6 | C18: =B18*0.0630902 -> 0.92111692
A19: 11 | B19: 15.4 | C19: =B19*0.0630902 -> 0.97158908
A20: 12 | B20: 16 | C20: =B20*0.0630902 -> 1.0094432
... A44: 200 | B44: 65 | C44: =B44*0.0630902 -> 4.100863
A46: 2. RAS 2000 – NIVEL DE COMPLEJIDAD Y PARÁMETROS ASOCIADOS
B47: Tabla A.3.1 (nivel por población), B.2.2 (dotación neta mín./máx.), B.2.4 (pérdidas técnicas máx.), B.2.5 (k1), B.2.6 (k2, red menor de distribución), período de diseño (RAS 2000).
A48: Nivel | B48: Población desde (hab) | C48: Dot. neta mín. (L/hab·d) | D48: Dot. neta máx. (L/hab·d) | E48: % pérdidas máx. | F48: k1 | G48: k2 | H48: Período diseño (años)
A49: BAJO | B49: 0 | C49: 100 | D49: 150 | E49: 0.4 | F49: 1.3 | G49: 1.6 | H49: 15
A50: MEDIO | B50: 2501 | C50: 120 | D50: 175 | E50: 0.3 | F50: 1.3 | G50: 1.6 | H50: 20
A51: MEDIO ALTO | B51: 12501 | C51: 130 | D51: 175 | E51: 0.25 | F51: 1.2 | G51: 1.5 | H51: 25
A52: ALTO | B52: 60001 | C52: 150 | D52: 200 | E52: 0.2 | F52: 1.2 | G52: 1.5 | H52: 30
A54: 3. TUBERÍA PVC SANITARIA – DIÁMETROS INTERNOS
B55: Valores típicos de catálogo PVC sanitaria (NTC 1087). Verificar con el fabricante seleccionado.
A56: Ø nominal | B56: Ø (pulg) | C56: Ø externo (mm) | D56: Espesor (mm) | E56: Ø interno (mm)
A57: 1-1/2" | B57: 1.5 | C57: 48.26 | D57: 1.6 | E57: =C57-2*D57 -> 45.06
A58: 2" | B58: 2 | C58: 60.32 | D58: 1.8 | E58: =C58-2*D58 -> 56.72
A59: 3" | B59: 3 | C59: 88.9 | D59: 2 | E59: =C59-2*D59 -> 84.9
A60: 4" | B60: 4 | C60: 114.3 | D60: 2.4 | E60: =C60-2*D60 -> 109.5
A61: 6" | B61: 6 | C61: 168.28 | D61: 3.3 | E61: =C61-2*D61 -> 161.68
A63: 4. CAPACIDAD MÁXIMA DE DESAGÜES EN UNIDADES DE DESCARGA (UD)
