Workbook

Sheet Datos
A1: MEMORIA DE CÁLCULO – INSTALACIONES HIDRÁULICAS DE AGUA POTABLE
A2: DATOS GENERALES, NORMATIVA Y PROGRAMA ARQUITECTÓNICO
A3: Proyecto: Vivienda campestre unifamiliar – Restrepo (Valle del Cauca) | Rev. 0 | PENDIENTE: ajustar con planos arquitectónicos (D:\trabajo\proyecto\en curso\casa Restrepo)
B5: Leyenda: celdas AMARILLAS con texto AZUL = datos de entrada editables. Texto NEGRO = fórmulas. Texto VERDE = vínculos a otras hojas. Verificaciones en verde (CUMPLE) / rojo (NO CUMPLE).
B6: PENDIENTE: ajustar con planos arquitectónicos (D:\trabajo\proyecto\en curso\casa Restrepo)
A8: 1. IDENTIFICACIÓN DEL PROYECTO
A9: Ítem | B9: Descripción | C9: Símbolo | D9: Valor | E9: Unidad | F9: Referencia normativa / criterio / observación
A10: 1.1 | B10: Proyecto | D10: Vivienda campestre unifamiliar
A11: 1.2 | B11: Municipio / departamento | D11: Restrepo, Valle del Cauca
A12: 1.3 | B12: Zona | D12: Rural – suelo suburbano / rural (verificar EOT Restrepo) | F12: Verificar uso del suelo en EOT municipal
A13: 1.4 | B13: Altitud media del predio | C13: z | D13: 1400 | E13: msnm | F13: PENDIENTE: confirmar con levantamiento topográfico
A14: 1.5 | B14: Temperatura media anual | C14: T | D14: 20 | E14: °C | F14: Valor de referencia regional; confirmar con estación IDEAM más cercana
A15: 1.6 | B15: Autoridad ambiental | D15: CVC – Corporación Autónoma Regional del Valle del Cauca | F15: Permiso de vertimientos: Decreto 1076/2015
A16: 1.7 | B16: Fuente de abastecimiento | D16: Acueducto veredal / rural (punto de conexión) | F16: PENDIENTE: certificado de disponibilidad del prestador
A17: 1.8 | B17: Disposición de aguas residuales | D17: Sistema individual in situ: TG + TS + FAFA + campo de infiltración | F17: Sin red de alcantarillado público disponible
A18: 1.9 | B18: Revisión / fecha | D18: Rev. 0 – borrador para ajuste con planos
A20: 2. PROGRAMA ARQUITECTÓNICO (EDITAR SEGÚN PLANOS)
A21: Ítem | B21: Descripción | C21: Símbolo | D21: Valor | E21: Unidad | F21: Referencia normativa / criterio / observación
A22: 2.1 | B22: Alcobas principales | C22: Na | D22: 3 | E22: und | F22: PENDIENTE: ajustar con planos arquitectónicos (D:\trabajo\proyecto\en curso\casa Restrepo)
A23: 2.2 | B23: Alcobas de servicio | C23: Nas | D23: 1 | E23: und | F23: PENDIENTE: ajustar con planos arquitectónicos (D:\trabajo\proyecto\en curso\casa Restrepo)
A24: 2.3 | B24: Baños completos (sanitario + lavamanos + ducha) | C24: Nbc | D24: 2 | E24: und | F24: PENDIENTE: ajustar con planos arquitectónicos (D:\trabajo\proyecto\en curso\casa Restrepo)
A25: 2.4 | B25: Baños sociales (sanitario + lavamanos) | C25: Nbs | D25: 1 | E25: und | F25: PENDIENTE: ajustar con planos arquitectónicos (D:\trabajo\proyecto\en curso\casa Restrepo)
A26: 2.5 | B26: Cocinas (lavaplatos) | C26: Nc | D26: 1 | E26: und | F26: PENDIENTE: ajustar con planos arquitectónicos (D:\trabajo\proyecto\en curso\casa Restrepo)
A27: 2.6 | B27: Zonas de ropas (lavadero + lavadora) | C27: Nr | D27: 1 | E27: und | F27: PENDIENTE: ajustar con planos arquitectónicos (D:\trabajo\proyecto\en curso\casa Restrepo)
A28: 2.7 | B28: Zona BBQ / kiosco (lavaplatos exterior) | C28: Nbbq | D28: 1 | E28: und | F28: PENDIENTE: ajustar con planos arquitectónicos (D:\trabajo\proyecto\en curso\casa Restrepo)
A29: 2.8 | B29: Llaves de jardín / manguera | C29: Nj | D29: 2 | E29: und | F29: PENDIENTE: ajustar con planos arquitectónicos (D:\trabajo\proyecto\en curso\casa Restrepo)
A30: 2.9 | B30: Número de pisos | C30: Np | D30: 1 | E30: und | F30: PENDIENTE: ajustar con planos arquitectónicos (D:\trabajo\proyecto\en curso\casa Restrepo)
A31: 2.10 | B31: Área de cubierta (proyección horizontal) | C31: Ac | D31: 180 | E31: m² | F31: PENDIENTE: ajustar con planos arquitectónicos (D:\trabajo\proyecto\en curso\casa Restrepo)
A32: 2.11 | B32: Área de patios / terrazas duras drenadas | C32: Ap | D32: 40 | E32: m² | F32: PENDIENTE: ajustar con planos arquitectónicos (D:\trabajo\proyecto\en curso\casa Restrepo)
A33: 2.12 | B33: Área de zonas verdes / jardín con riego | C33: Av | D33: 300 | E33: m² | F33: PENDIENTE: ajustar con planos arquitectónicos (D:\trabajo\proyecto\en curso\casa Restrepo)
A35: 3. MARCO NORMATIVO APLICADO
B36: • RAS 2000 – Reglamento Técnico del Sector de Agua Potable y Saneamiento Básico (Res. 1096/2000): Título A (nivel de complejidad), Título B (población, dotación, caudales), Título D (alcantarillados), Título E (tratamiento de aguas residuales – sistemas in situ).
B37: • Resolución 0330 de 2017 (MinVivienda), modificada por la Res. 0799 de 2021 – reglamento técnico vigente (dotación neta máxima, pérdidas, coeficientes de diseño). Prevalece sobre RAS 2000 donde difieren.
B38: • NTC 1500:2017 – Código colombiano de instalaciones hidráulicas y sanitarias (aparatos, presiones, unidades de consumo y de descarga, ventilación, aguas lluvias).
B39: • Decreto 1077 de 2015 (sector vivienda) y Decreto 1076 de 2015 (sector ambiente – permiso de vertimientos ante la CVC).
B40: • Resolución 699 de 2021 (MinAmbiente) – vertimientos de ARD tratadas al suelo.
B41: • Criterios complementarios de referencia: NBR 7229/1993 y NBR 13969/1997 (tanque séptico y filtro anaerobio, base de las fórmulas del RAS 2000 Título E); USPHS Manual of Septic-Tank Practice (1967) – percolación; IPC (International Plumbing Code) – tablas de capacidad de desagües y bajantes pluviales.
B42: • NTC 1063 (ISO 4064) – medidores de agua potable.
B44: NOTA: los valores de tablas normativas transcritos en la hoja "Tablas" deben verificarse contra la edición vigente de cada norma antes de radicar la memoria.

Sheet Poblacion
A1: MEMORIA DE CÁLCULO – INSTALACIONES HIDRÁULICAS DE AGUA POTABLE
A2: CÁLCULO DE POBLACIÓN DE DISEÑO POR USOS Y NIVEL DE COMPLEJIDAD (RAS 2000)
A3: Proyecto: Vivienda campestre unifamiliar – Restrepo (Valle del Cauca) | Rev. 0 | PENDIENTE: ajustar con planos arquitectónicos (D:\trabajo\proyecto\en curso\casa Restrepo)
B5: La vivienda unifamiliar no requiere proyección demográfica (RAS 2000 B.2.2): la población se fija por capacidad de ocupación (alcobas) y se discrimina por tipo de uso/ocupante (permanente, servicio, flotante, empleados), conforme a RAS 2000 B.2.3 (usos) y B.2.4 (dotación por uso).
A7: 1. PARÁMETROS DE OCUPACIÓN
A8: Ítem | B8: Descripción | C8: Símbolo | D8: Valor | E8: Unidad | F8: Referencia normativa / criterio / observación
A9: 1.1 | B9: Ocupación por alcoba principal | C9: ha | D9: 2 | E9: hab/alcoba | F9: Criterio usual de diseño de instalaciones internas (2 hab/alcoba)
A10: 1.2 | B10: Ocupación por alcoba de servicio | C10: hs | D10: 1 | E10: hab/alcoba | F10: Criterio usual de diseño
A11: 1.3 | B11: Población flotante – visitantes que pernoctan (ocupación pico fin de semana) | C11: Nv | D11: 4 | E11: hab | F11: Uso recreacional campestre; PENDIENTE confirmar con propietario
A12: 1.4 | B12: Población flotante – empleados sin pernoctación (mayordomo, jardinero, aseo) | C12: Ne | D12: 2 | E12: emp | F12: PENDIENTE confirmar con propietario
A14: 2. POBLACIÓN DE DISEÑO POR USOS
A15: Ítem | B15: Descripción | C15: Símbolo | D15: Valor | E15: Unidad | F15: Referencia normativa / criterio / observación
A16: 2.1 | B16: Población residente permanente = Na × ha | C16: Pr | D16: =Datos!$D$22*$D$9 -> 6 | E16: hab | F16: RAS 2000 B.2.3 – uso residencial
A17: 2.2 | B17: Población de servicio doméstico = Nas × hs | C17: Ps | D17: =Datos!$D$23*$D$10 -> 1 | E17: hab | F17: Uso residencial (pernocta)
A18: 2.3 | B18: Población flotante que pernocta | C18: Pf | D18: =$D$11 -> 4 | E18: hab | F18: RAS 2000 B.2.3 – población flotante
A19: 2.4 | B19: Población con pernoctación (diseño residencial) = Pr + Ps + Pf | C19: Pp | D19: =$D$16+$D$17+$D$18 -> 11 | E19: hab | F19: Se diseña para ocupación pico (casa campestre)
A20: 2.5 | B20: Población flotante diurna (empleados) | C20: Pe | D20: =$D$12 -> 2 | E20: emp | F20: Uso de servicio – dotación reducida
A21: 2.6 | B21: Población total de diseño = Pp + Pe | C21: Pd | D21: =$D$19+$D$20 -> 13 | E21: hab
A23: 3. NIVEL DE COMPLEJIDAD DEL SISTEMA (RAS 2000 TABLA A.3.1)
A24: Ítem | B24: Descripción | C24: Símbolo | D24: Valor | E24: Unidad | F24: Referencia normativa / criterio / observación
A25: 3.1 | B25: Índice de nivel según población servida | C25: i | D25: =MATCH($D$21,Tablas!$B$49:$B$52,1) -> 1 | F25: Bajo ≤ 2.500 hab; Medio 2.501–12.500; Medio alto 12.501–60.000; Alto > 60.000
A26: 3.2 | B26: Nivel de complejidad | C26: NC | D26: =INDEX(Tablas!$A$49:$A$52,$D$25) -> BAJO | F26: Sistema individual unifamiliar → BAJO
A27: 3.3 | B27: Período de diseño de referencia (RAS 2000) | C27: n | D27: =INDEX(Tablas!$H$49:$H$52,$D$25) -> 15 | E27: años | F27: Res. 0330/2017 fija 25 años para sistemas nuevos; en vivienda la población no varía con el horizonte
A29: 4. DOTACIÓN NETA POR USO (RAS 2000 B.2.4 – RES. 0330/2017 ART. 43)
A30: Ítem | B30: Descripción | C30: Símbolo | D30: Valor | E30: Unidad | F30: Referencia normativa / criterio / observación
A31: 4.1 | B31: Dotación neta mínima RAS 2000 para el nivel | C31: dmín | D31: =INDEX(Tablas!$C$49:$C$52,$D$25) -> 100 | E31: L/hab·d | F31: RAS 2000 Tabla B.2.2
A32: 4.2 | B32: Dotación neta máxima RAS 2000 para el nivel | C32: dmáx | D32: =INDEX(Tablas!$D$49:$D$52,$D$25) -> 150 | E32: L/hab·d | F32: RAS 2000 Tabla B.2.2
A33: 4.3 | B33: Dotación neta base seleccionada (RAS 2000) | C33: d0 | D33: 120 | E33: L/hab·d | F33: Entre dmín y dmáx según usos de la vivienda
A34: 4.4 | B34: Dotación base dentro del rango RAS 2000 | C34: ✓ | D34: =IF(AND($D$33>=$D$31,$D$33<=$D$32),"CUMPLE","NO CUMPLE") -> CUMPLE | F34: RAS 2000 Tabla B.2.2
A35: 4.5 | B35: Corrección por clima (T media) | C35: Δc | D35: =IF(Datos!$D$14>28,0.15,IF(Datos!$D$14>=20,0.1,0)) -> 0.1 | E35: % | F35: RAS 2000 Tabla B.2.3: cálido (>28 °C) +15 %; templado (20–28 °C) +10 %; frío (<20 °C) sin corrección
A36: 4.6 | B36: Dotación neta corregida RAS 2000 = d0 × (1 + Δc) | C36: dRAS | D36: =$D$33*(1+$D$35) -> 132 | E36: L/hab·d
A37: 4.7 | B37: Dotación neta máxima Res. 0330/2017 según altitud | C37: d0330 | D37: =IF(Datos!$D$13>2000,120,IF(Datos!$D$13>=1000,130,140)) -> 130 | E37: L/hab·d | F37: Art. 43: >2.000 msnm: 120; 1.000–2.000 msnm: 130; <1.000 msnm: 140 L/hab·d
A38: 4.8 | B38: Dotación neta adoptada – uso residencial = MÍN(dRAS; d0330) | C38: dn | D38: =MIN($D$36,$D$37) -> 130 | E38: L/hab·d | F38: Se adopta el menor valor (norma vigente prevalece)
A39: 4.9 | B39: Dotación neta – empleados sin pernoctación | C39: de | D39: 50 | E39: L/emp·d | F39: Criterio para personal de jornada diurna (NBR 7229 – ocupantes temporales: 50 L/pers·d)
A41: 5. CONSUMO NETO POR USOS
B42: Uso / tipo de ocupante | C42: Población (hab) | D42: Dotación neta (L/hab·d) | E42: Consumo neto (L/d)
B43: Residentes permanentes | C43: =$D$16 -> 6 | D43: =$D$38 -> 130 | E43: =C43*D43 -> 780
B44: Servicio doméstico | C44: =$D$17 -> 1 | D44: =$D$38 -> 130 | E44: =C44*D44 -> 130
B45: Flotante – visitantes que pernoctan | C45: =$D$18 -> 4 | D45: =$D$38 -> 130 | E45: =C45*D45 -> 520
B46: Flotante – empleados diurnos | C46: =$D$20 -> 2 | D46: =$D$39 -> 50 | E46: =C46*D46 -> 100
...

Sheet Dotacion_Caudales
A1: MEMORIA DE CÁLCULO – INSTALACIONES HIDRÁULICAS DE AGUA POTABLE
A2: DOTACIÓN BRUTA Y CAUDALES DE DISEÑO
A3: Proyecto: Vivienda campestre unifamiliar – Restrepo (Valle del Cauca) | Rev. 0 | PENDIENTE: ajustar con planos arquitectónicos (D:\trabajo\proyecto\en curso\casa Restrepo)
A6: 1. PÉRDIDAS TÉCNICAS
A7: Ítem | B7: Descripción | C7: Símbolo | D7: Valor | E7: Unidad | F7: Referencia normativa / criterio / observación
A8: 1.1 | B8: Pérdidas técnicas máximas RAS 2000 para el nivel | C8: pRAS | D8: =INDEX(Tablas!$E$49:$E$52,Poblacion!$D$25) -> 0.4 | E8: % | F8: RAS 2000 Tabla B.2.4
A9: 1.2 | B9: Porcentaje de pérdidas técnicas adoptado | C9: p | D9: 0.25 | E9: % | F9: Res. 0330/2017 art. 44: máximo 25 % para diseño
A10: 1.3 | B10: Pérdidas adoptadas ≤ 25 % (Res. 0330/2017) | C10: ✓ | D10: =IF($D$9<=0.25,"CUMPLE","NO CUMPLE") -> CUMPLE | F10: Res. 0330/2017 art. 44
A12: 2. DOTACIÓN BRUTA
A13: Ítem | B13: Descripción | C13: Símbolo | D13: Valor | E13: Unidad | F13: Referencia normativa / criterio / observación
A14: 2.1 | B14: Dotación bruta residencial = dn / (1 − p) | C14: dbr | D14: =Poblacion!$D$38/(1-$D$9) -> 173.33333 | E14: L/hab·d | F14: RAS 2000 B.2.6 / Res. 0330/2017 art. 44
A15: 2.2 | B15: Dotación bruta empleados = de / (1 − p) | C15: dbe | D15: =Poblacion!$D$39/(1-$D$9) -> 66.666667 | E15: L/emp·d
A16: 2.3 | B16: Consumo bruto doméstico = Consumo neto / (1 − p) | C16: Cb | D16: =Poblacion!$E$47/(1-$D$9) -> 2040 | E16: L/d | F16: Consumo neto: hoja Poblacion
A18: 3. USOS ADICIONALES
A19: Ítem | B19: Descripción | C19: Símbolo | D19: Valor | E19: Unidad | F19: Referencia normativa / criterio / observación
A20: 3.1 | B20: Incluir riego de jardín con agua potable (1 = sí, 0 = no) | C20: Ir | D20: 1 | F20: Recomendable usar aguas lluvias para riego
A21: 3.2 | B21: Lámina de riego | C21: qr | D21: 2 | E21: L/m²·d | F21: Criterio usual de diseño (NTC 1500 – riego de jardines)
A22: 3.3 | B22: Consumo por riego = Av × qr × Ir | C22: Criego | D22: =Datos!$D$33*$D$21*$D$20 -> 600 | E22: L/d
A24: 4. CAUDALES DE DISEÑO
A25: Ítem | B25: Descripción | C25: Símbolo | D25: Valor | E25: Unidad | F25: Referencia normativa / criterio / observación
A26: 4.1 | B26: Caudal medio diario Qmd = (Cb + Criego) / 86.400 | C26: Qmd | D26: =($D$16+$D$22)/86400 -> 0.030555556 | E26: L/s | F26: RAS 2000 B.2.7.1
A27: 4.2 | B27: Caudal medio diario | C27: Qmd | D27: =$D$26*86.4 -> 2.64 | E27: m³/d
A28: 4.3 | B28: Coeficiente de consumo máximo diario k1 | C28: k1 | D28: =INDEX(Tablas!$F$49:$F$52,Poblacion!$D$25) -> 1.3 | F28: RAS 2000 Tabla B.2.5; Res. 0330/2017 (k1 = 1,30)
A29: 4.4 | B29: Caudal máximo diario QMD = k1 × Qmd | C29: QMD | D29: =$D$28*$D$26 -> 0.039722222 | E29: L/s | F29: RAS 2000 B.2.7.2
A30: 4.5 | B30: Coeficiente de consumo máximo horario k2 | C30: k2 | D30: =INDEX(Tablas!$G$49:$G$52,Poblacion!$D$25) -> 1.6 | F30: RAS 2000 Tabla B.2.6 (red menor de distribución)
A31: 4.6 | B31: Caudal máximo horario QMH = k2 × QMD | C31: QMH | D31: =$D$30*$D$29 -> 0.063555556 | E31: L/s | F31: RAS 2000 B.2.7.3
B32: El caudal instantáneo de la red interna se determina por el método de Hunter (hoja UC_Hunter), que gobierna el dimensionamiento de tuberías y del equipo de presión. QMD gobierna la acometida y QMH se reporta al prestador.

Sheet Almacenamiento
A1: MEMORIA DE CÁLCULO – INSTALACIONES HIDRÁULICAS DE AGUA POTABLE
A2: TANQUE DE RESERVA DE AGUA POTABLE
A3: Proyecto: Vivienda campestre unifamiliar – Restrepo (Valle del Cauca) | Rev. 0 | PENDIENTE: ajustar con planos arquitectónicos (D:\trabajo\proyecto\en curso\casa Restrepo)
B5: Esquema adoptado: acometida del acueducto veredal → medidor → tanque de reserva a nivel de terreno → equipo de presión → red interna. Se justifica por suministro rural intermitente y presión de red no garantizada.
A7: 1. VOLUMEN REQUERIDO
A8: Ítem | B8: Descripción | C8: Símbolo | D8: Valor | E8: Unidad | F8: Referencia normativa / criterio / observación
A9: 1.1 | B9: Consumo diario a almacenar = Consumo neto + Criego | C9: Cd | D9: =Poblacion!$E$47+Dotacion_Caudales!$D$22 -> 2130 | E9: L/d | F9: Las pérdidas técnicas corresponden a la red de distribución, no al consumo interno
A10: 1.2 | B10: Días de reserva | C10: nd | D10: 1 | E10: d | F10: NTC 1500: reserva mínima equivalente al consumo de 1 día; en zona rural se recomienda 1–2 días
A11: 1.3 | B11: Volumen para protección contra incendio | C11: Vi | D11: 0 | E11: L | F11: No exigido para vivienda unifamiliar (NSR-10 Títulos J y K)
A12: 1.4 | B12: Volumen requerido = Cd × nd + Vi | C12: Vreq | D12: =$D$9*$D$10+$D$11 -> 2130 | E12: L
A14: 2. SELECCIÓN DEL TANQUE
A15: Ítem | B15: Descripción | C15: Símbolo | D15: Valor | E15: Unidad | F15: Referencia normativa / criterio / observación
A16: 2.1 | B16: Capacidad del tanque comercial | C16: Vt | D16: 2000 | E16: L | F16: Tanque plástico tipo comercial (NTC 4080)
A17: 2.2 | B17: Número de tanques = REDONDEAR.MAS(Vreq / Vt) | C17: n | D17: =ROUNDUP($D$12/$D$16,0) -> 2 | E17: und
A18: 2.3 | B18: Volumen instalado = n × Vt | C18: Vinst | D18: =$D$17*$D$16 -> 4000 | E18: L
A19: 2.4 | B19: Volumen instalado ≥ volumen requerido | C19: ✓ | D19: =IF($D$18>=$D$12,"CUMPLE","NO CUMPLE") -> CUMPLE
A20: 2.5 | B20: Autonomía con consumo medio | C20: ta | D20: =$D$18/$D$9*24 -> 45.070423 | E20: h
A21: 2.6 | B21: Tiempo de llenado con caudal de acometida | C21: tll | D21: =$D$18/(Acometida_Medidor!$D$18*3600) -> 6 | E21: h | F21: Ver hoja Acometida_Medidor
A23: 3. ALTERNATIVA: TANQUE EN CONCRETO (INFORMATIVO)
A24: Ítem | B24: Descripción | C24: Símbolo | D24: Valor | E24: Unidad | F24: Referencia normativa / criterio / observación
A25: 3.1 | B25: Altura útil | C25: hu | D25: 1.2 | E25: m | F25: Más borde libre ≥ 0,30 m
A26: 3.2 | B26: Área en planta requerida = Vreq / hu | C26: A | D26: =$D$12/1000/$D$25 -> 1.775 | E26: m²
A27: 3.3 | B27: Ancho (relación L/B = 1,5) | C27: B | D27: =SQRT($D$26/1.5) -> 1.0878113 | E27: m
A28: 3.4 | B28: Largo | C28: L | D28: =1.5*$D$27 -> 1.6317169 | E28: m

Sheet UC_Hunter
A1: MEMORIA DE CÁLCULO – INSTALACIONES HIDRÁULICAS DE AGUA POTABLE
A2: UNIDADES DE CONSUMO Y CAUDAL MÁXIMO PROBABLE (MÉTODO DE HUNTER)
A3: Proyecto: Vivienda campestre unifamiliar – Restrepo (Valle del Cauca) | Rev. 0 | PENDIENTE: ajustar con planos arquitectónicos (D:\trabajo\proyecto\en curso\casa Restrepo)
B5: Cantidades vinculadas al programa arquitectónico (hoja Datos). UC por aparato de uso privado (NTC 1500 – Hunter).
B6: PENDIENTE: ajustar con planos arquitectónicos (D:\trabajo\proyecto\en curso\casa Restrepo)
A8: 1. UNIDADES DE CONSUMO POR APARATO
A9: Aparato | B9: Cantidad (und) | C9: UC por aparato | D9: UC totales | E9: Ø mín. alimentación | F9: Presión mín. de servicio (m.c.a.)
A10: Sanitario con tanque | B10: =Datos!$D$24+Datos!$D$25 -> 3 | C10: 3 | D10: =B10*C10 -> 9 | E10: 1/2" | F10: 2
A11: Lavamanos | B11: =Datos!$D$24+Datos!$D$25 -> 3 | C11: 1 | D11: =B11*C11 -> 3 | E11: 1/2" | F11: 2
A12: Ducha | B12: =Datos!$D$24 -> 2 | C12: 2 | D12: =B12*C12 -> 4 | E12: 1/2" | F12: 3
A13: Lavaplatos cocina | B13: =Datos!$D$26 -> 1 | C13: 2 | D13: =B13*C13 -> 2 | E13: 1/2" | F13: 2
A14: Lavaplatos BBQ / kiosco | B14: =Datos!$D$28 -> 1 | C14: 2 | D14: =B14*C14 -> 2 | E14: 1/2" | F14: 2
A15: Lavadero | B15: =Datos!$D$27 -> 1 | C15: 3 | D15: =B15*C15 -> 3 | E15: 1/2" | F15: 2
A16: Lavadora | B16: =Datos!$D$27 -> 1 | C16: 2 | D16: =B16*C16 -> 2 | E16: 1/2" | F16: 5
A17: Llave de jardín / manguera | B17: =Datos!$D$29 -> 2 | C17: 2 | D17: =B17*C17 -> 4 | E17: 1/2" | F17: 2
A18: TOTAL | B18: =SUM(B10:B17) -> 14 | D18: =SUM(D10:D17) -> 29 | F18: =MAX(F10:F17) -> 5
A20: Caudal máximo probable Q = f(ΣUC) – interpolación curva de Hunter (L/s) | D20: =IF(($D$18)<=MIN(Tablas!$A$9:$A$44),INDEX(Tablas!$C$9:$C$44,1),IF(($D$18)>=MAX(Tablas!$A$9:$A$44),INDEX(Tablas!$C$9:$C$44,ROWS(Tablas!$A$9:$A$44)),INDEX(Tablas!$C$9:$C$44,MATCH(($D$18),Tablas!$A$9:$A$44,1))+(($D$18)-INDEX(Tablas!$A$9:$A$44,MATCH(($D$18),Tablas!$A$9:$A$44,1)))*(INDEX(Tablas!$C$9:$C$44,MATCH(($D$18),Tablas!$A$9:$A$44,1)+1)-INDEX(Tablas!$C$9:$C$44,MATCH(($D$18),Tablas!$A$9:$A$44,1)))/(INDEX(Tablas!$A$9:$A$44,MATCH(($D$18),Tablas!$A$9:$A$44,1)+1)-INDEX(Tablas!$A$9:$A$44,MATCH(($D$18),Tablas!$A$9:$A$44,1))))) -> 1.4472892 | G20: Gobierna la red interna y el equipo de presión
A21: Relación Q Hunter / QMH (simultaneidad instantánea vs. horaria) | D21: =$D$20/Dotacion_Caudales!$D$31 -> 22.772033

Sheet Tramos
A1: MEMORIA DE CÁLCULO – INSTALACIONES HIDRÁULICAS DE AGUA POTABLE
A2: DISEÑO HIDRÁULICO DE TRAMOS HASTA EL APARATO CRÍTICO (HAZEN-WILLIAMS)
A3: Proyecto: Vivienda campestre unifamiliar – Restrepo (Valle del Cauca) | Rev. 0 | PENDIENTE: ajustar con planos arquitectónicos (D:\trabajo\proyecto\en curso\casa Restrepo)
B5: Ruta crítica: equipo de presión → aparato más desfavorable (mayor pérdida + mayor cota). UC acumuladas, longitudes y accesorios son SUPUESTOS hasta disponer de planos; agregar filas copiando la última si la ruta tiene más tramos.
B6: PENDIENTE: ajustar con planos arquitectónicos (D:\trabajo\proyecto\en curso\casa Restrepo)
A8: 1. PARÁMETROS DE DISEÑO
A9: Coeficiente de Hazen-Williams PVC | C9: 150 | E9: RAS 2000 B.6 / NTC 1500 – PVC C = 150
A10: Velocidad máxima | C10: 2 | D10: m/s | E10: NTC 1500 – control de ruido y golpe de ariete (criterio ≤ 2,0 m/s)
A11: Presión al inicio de la red (arranque del equipo de presión) | C11: 14.06 | D11: m.c.a. | E11: 20 psi; ver hoja Equipo_Presion
A12: Presión mínima residual en el aparato crítico | C12: =UC_Hunter!$F$18 -> 5 | D12: m.c.a. | E12: Máx. presión mínima de servicio de los aparatos (hoja UC_Hunter); NTC 1500 ≥ 2 m.c.a.
A14: 2. CÁLCULO POR TRAMOS
A15: Tramo | B15: Descripción | C15: UC acumuladas | D15: Q (L/s) | E15: Ø nominal | F15: Ø interno (mm) | G15: V (m/s) | H15: L real (m) | I15: L equiv. accesorios (m) | J15: L total (m) | K15: J (m/m) | L15: hf (m) | M15: Δz (m) (+ sube) | N15: P inicial (m.c.a.) | O15: P final (m.c.a.) | P15: Verif. velocidad | Q15: Verif. presión
A16: T1 | B16: Equipo de presión → derivación general | C16: =UC_Hunter!$D$18 -> 29 | D16: =IF((C16)<=MIN(Tablas!$A$9:$A$44),INDEX(Tablas!$C$9:$C$44,1),IF((C16)>=MAX(Tablas!$A$9:$A$44),INDEX(Tablas!$C$9:$C$44,ROWS(Tablas!$A$9:$A$44)),INDEX(Tablas!$C$9:$C$44,MATCH((C16),Tablas!$A$9:$A$44,1))+((C16)-INDEX(Tablas!$A$9:$A$44,MATCH((C16),Tablas!$A$9:$A$44,1)))*(INDEX(Tablas!$C$9:$C$44,MATCH((C16),Tablas!$A$9:$A$44,1)+1)-INDEX(Tablas!$C$9:$C$44,MATCH((C16),Tablas!$A$9:$A$44,1)))/(INDEX(Tablas!$A$9:$A$44,MATCH((C16),Tablas!$A$9:$A$44,1)+1)-INDEX(Tablas!$A$9:$A$44,MATCH((C16),Tablas!$A$9:$A$44,1))))) -> 1.4472892 | E16: 1-1/4" | F16: =INDEX(Tablas!$E$57:$E$62,MATCH(E16,Tablas!$A$57:$A$62,0)) -> 38.14 | G16: =D16/1000/(PI()*(F16/1000)^2/4) -> 1.2667883 | H16: 8 | I16: 6 | J16: =H16+I16 -> 14 | K16: =10.67*(D16/1000)^1.852/($C$9^1.852*(F16/1000)^4.87) -> 0.044470079 | L16: =K16*J16 -> 0.62258111 | M16: 0.5 | N16: =$C$11 -> 14.06 | O16: =N16-L16-M16 -> 12.937419 | P16: =IF(G16<=$C$10,"CUMPLE","NO CUMPLE") -> CUMPLE | Q16: =IF(O16>=$C$12,"CUMPLE","NO CUMPLE") -> CUMPLE
A17: T2 | B17: Derivación general → zona de baños | C17: 16 | D17: =IF((C17)<=MIN(Tablas!$A$9:$A$44),INDEX(Tablas!$C$9:$C$44,1),IF((C17)>=MAX(Tablas!$A$9:$A$44),INDEX(Tablas!$C$9:$C$44,ROWS(Tablas!$A$9:$A$44)),INDEX(Tablas!$C$9:$C$44,MATCH((C17),Tablas!$A$9:$A$44,1))+((C17)-INDEX(Tablas!$A$9:$A$44,MATCH((C17),Tablas!$A$9:$A$44,1)))*(INDEX(Tablas!$C$9:$C$44,MATCH((C17),Tablas!$A$9:$A$44,1)+1)-INDEX(Tablas!$C$9:$C$44,MATCH((C17),Tablas!$A$9:$A$44,1)))/(INDEX(Tablas!$A$9:$A$44,MATCH((C17),Tablas!$A$9:$A$44,1)+1)-INDEX(Tablas!$A$9:$A$44,MATCH((C17),Tablas!$A$9:$A$44,1))))) -> 1.1356236 | E17: 1" | F17: =INDEX(Tablas!$E$57:$E$62,MATCH(E17,Tablas!$A$57:$A$62,0)) -> 30.22 | G17: =D17/1000/(PI()*(F17/1000)^2/4) -> 1.5832723 | H17: 10 | I17: 5 | J17: =H17+I17 -> 15 | K17: =10.67*(D17/1000)^1.852/($C$9^1.852*(F17/1000)^4.87) -> 0.088166482 | L17: =K17*J17 -> 1.3224972 | M17: 0 | N17: =O16 -> 12.937419 | O17: =N17-L17-M17 -> 11.614922 | P17: =IF(G17<=$C$10,"CUMPLE","NO CUMPLE") -> CUMPLE | Q17: =IF(O17>=$C$12,"CUMPLE","NO CUMPLE") -> CUMPLE
A18: T3 | B18: Zona de baños → baño principal | C18: 6 | D18: =IF((C18)<=MIN(Tablas!$A$9:$A$44),INDEX(Tablas!$C$9:$C$44,1),IF((C18)>=MAX(Tablas!$A$9:$A$44),INDEX(Tablas!$C$9:$C$44,ROWS(Tablas!$A$9:$A$44)),INDEX(Tablas!$C$9:$C$44,MATCH((C18),Tablas!$A$9:$A$44,1))+((C18)-INDEX(Tablas!$A$9:$A$44,MATCH((C18),Tablas!$A$9:$A$44,1)))*(INDEX(Tablas!$C$9:$C$44,MATCH((C18),Tablas!$A$9:$A$44,1)+1)-INDEX(Tablas!$C$9:$C$44,MATCH((C18),Tablas!$A$9:$A$44,1)))/(INDEX(Tablas!$A$9:$A$44,MATCH((C18),Tablas!$A$9:$A$44,1)+1)-INDEX(Tablas!$A$9:$A$44,MATCH((C18),Tablas!$A$9:$A$44,1))))) -> 0.67506514 | E18: 3/4" | F18: =INDEX(Tablas!$E$57:$E$62,MATCH(E18,Tablas!$A$57:$A$62,0)) -> 24.13 | G18: =D18/1000/(PI()*(F18/1000)^2/4) -> 1.4761863 | H18: 6 | I18: 4 | J18: =H18+I18 -> 10 | K18: =10.67*(D18/1000)^1.852/($C$9^1.852*(F18/1000)^4.87) -> 0.10067867 | L18: =K18*J18 -> 1.0067867 | M18: 0 | N18: =O17 -> 11.614922 | O18: =N18-L18-M18 -> 10.608135 | P18: =IF(G18<=$C$10,"CUMPLE","NO CUMPLE") -> CUMPLE | Q18: =IF(O18>=$C$12,"CUMPLE","NO CUMPLE") -> CUMPLE
A19: T4 | B19: Baño principal → ducha (aparato crítico) | C19: 2 | D19: =IF((C19)<=MIN(Tablas!$A$9:$A$44),INDEX(Tablas!$C$9:$C$44,1),IF((C19)>=MAX(Tablas!$A$9:$A$44),INDEX(Tablas!$C$9:$C$44,ROWS(Tablas!$A$9:$A$44)),INDEX(Tablas!$C$9:$C$44,MATCH((C19),Tablas!$A$9:$A$44,1))+((C19)-INDEX(Tablas!$A$9:$A$44,MATCH((C19),Tablas!$A$9:$A$44,1)))*(INDEX(Tablas!$C$9:$C$44,MATCH((C19),Tablas!$A$9:$A$44,1)+1)-INDEX(Tablas!$C$9:$C$44,MATCH((C19),Tablas!$A$9:$A$44,1)))/(INDEX(Tablas!$A$9:$A$44,MATCH((C19),Tablas!$A$9:$A$44,1)+1)-INDEX(Tablas!$A$9:$A$44,MATCH((C19),Tablas!$A$9:$A$44,1))))) -> 0.315451 | E19: 1/2" | F19: =INDEX(Tablas!$E$57:$E$62,MATCH(E19,Tablas!$A$57:$A$62,0)) -> 18.18 | G19: =D19/1000/(PI()*(F19/1000)^2/4) -> 1.2152182 | H19: 3 | I19: 3 | J19: =H19+I19 -> 6 | K19: =10.67*(D19/1000)^1.852/($C$9^1.852*(F19/1000)^4.87) -> 0.097688426 | L19: =K19*J19 -> 0.58613056 | M19: 1.8 | N19: =O18 -> 10.608135 | O19: =N19-L19-M19 -> 8.2220044 | P19: =IF(G19<=$C$10,"CUMPLE","NO CUMPLE") -> CUMPLE | Q19: =IF(O19>=$C$12,"CUMPLE","NO CUMPLE") -> CUMPLE
A21: Caudal de diseño de la red (tramo inicial) | C21: =D16 -> 1.4472892
A22: Pérdida total en la ruta crítica Σhf | C22: =SUM(L16:L19) -> 3.5379956
A23: Desnivel total en la ruta crítica ΣΔz | C23: =SUM(M16:M19) -> 2.3
A24: Presión residual en el aparato crítico | C24: =O19 -> 8.2220044
B26: Longitudes equivalentes de accesorios según tablas de fabricante (codos, tees, válvulas, registros). J = 10,67·Q^1,852 / (C^1,852·D^4,87) con Q en m³/s y D en m.
A27: Velocidad ≤ Vmáx en todos los tramos | C27: =IF(COUNTIF(P16:P19,"NO CUMPLE")=0,"CUMPLE","NO CUMPLE") -> CUMPLE
A28: Presión residual ≥ presión mínima en la ruta crítica | C28: =IF(COUNTIF(Q16:Q19,"NO CUMPLE")=0,"CUMPLE","NO CUMPLE") -> CUMPLE

Sheet Acometida_Medidor
A1: MEMORIA DE CÁLCULO – INSTALACIONES HIDRÁULICAS DE AGUA POTABLE
A2: ACOMETIDA Y MEDIDOR
A3: Proyecto: Vivienda campestre unifamiliar – Restrepo (Valle del Cauca) | Rev. 0 | PENDIENTE: ajustar con planos arquitectónicos (D:\trabajo\proyecto\en curso\casa Restrepo)
A6: 1. DATOS
A7: Ítem | B7: Descripción | C7: Símbolo | D7: Valor | E7: Unidad | F7: Referencia normativa / criterio / observación
A8: 1.1 | B8: Presión disponible en la red veredal en el punto de conexión | C8: Pr | D8: 10 | E8: m.c.a. | F8: PENDIENTE: certificado del prestador
A9: 1.2 | B9: Longitud de acometida hasta el tanque | C9: La | D9: 25 | E9: m | F9: PENDIENTE: ajustar con planos arquitectónicos (D:\trabajo\proyecto\en curso\casa Restrepo)
A10: 1.3 | B10: Longitud equivalente de accesorios (registro, medidor, válvula flotador) | C10: Le | D10: 8 | E10: m
A11: 1.4 | B11: Desnivel red → entrada del tanque (+ sube) | C11: Δz | D11: 0.5 | E11: m
A12: 1.5 | B12: Tiempo objetivo de llenado del tanque | C12: to | D12: 6 | E12: h | F12: Criterio de diseño (reposición nocturna)
A13: 1.6 | B13: Diámetro nominal de acometida | C13: Ø | D13: 3/4" | F13: Lista desplegable
A14: 1.7 | B14: Presión mínima en la válvula de flotador | C14: Pf | D14: 2 | E14: m.c.a. | F14: NTC 1500 ≥ 2 m.c.a.
A16: 2. CÁLCULO HIDRÁULICO
A17: Ítem | B17: Descripción | C17: Símbolo | D17: Valor | E17: Unidad | F17: Referencia normativa / criterio / observación
A18: 2.1 | B18: Caudal de acometida = MÁX(QMD; Vinst / (to·3600)) | C18: Qa | D18: =MAX(Dotacion_Caudales!$D$29,Almacenamiento!$D$18/($D$12*3600)) -> 0.18518519 | E18: L/s | F18: Ver hojas Dotacion_Caudales y Almacenamiento
A19: 2.2 | B19: Diámetro interno | C19: Di | D19: =INDEX(Tablas!$E$57:$E$62,MATCH($D$13,Tablas!$A$57:$A$62,0)) -> 24.13 | E19: mm | F19: Hoja Tablas
A20: 2.3 | B20: Velocidad | C20: V | D20: =$D$18/1000/(PI()*($D$19/1000)^2/4) -> 0.40495029 | E20: m/s
A21: 2.4 | B21: Velocidad en acometida ≤ Vmáx | C21: ✓ | D21: =IF($D$20<=Tramos!$C$10,"CUMPLE","NO CUMPLE") -> CUMPLE | F21: NTC 1500
A22: 2.5 | B22: Pérdidas (Hazen-Williams) = J × (La + Le) | C22: hf | D22: =10.67*($D$18/1000)^1.852/(Tramos!$C$9^1.852*($D$19/1000)^4.87)*($D$9+$D$10) -> 0.30276798 | E22: m
A23: 2.6 | B23: Presión en la entrada del tanque = Pr − hf − Δz | C23: Pe | D23: =$D$8-$D$22-$D$11 -> 9.197232 | E23: m.c.a.
A24: 2.7 | B24: Presión en flotador ≥ mínima | C24: ✓ | D24: =IF($D$23>=$D$14,"CUMPLE","NO CUMPLE") -> CUMPLE | F24: NTC 1500
A26: 3. MEDIDOR
A27: Ítem | B27: Descripción | C27: Símbolo | D27: Valor | E27: Unidad | F27: Referencia normativa / criterio / observación
A28: 3.1 | B28: Caudal de acometida | C28: Qa | D28: =$D$18*3.6 -> 0.66666667 | E28: m³/h
A29: 3.2 | B29: Caudal permanente del medidor (mismo Ø de acometida) | C29: Q3 | D29: =INDEX(Tablas!$B$67:$B$72,MATCH($D$13,Tablas!$A$67:$A$72,0)) -> 4 | E29: m³/h | F29: NTC 1063-1 (ISO 4064)
A30: 3.3 | B30: Caudal de acometida ≤ Q3 del medidor | C30: ✓ | D30: =IF($D$28<=$D$29,"CUMPLE","NO CUMPLE") -> CUMPLE | F30: NTC 1063-1

Sheet Equipo_Presion
A1: MEMORIA DE CÁLCULO – INSTALACIONES HIDRÁULICAS DE AGUA POTABLE
A2: EQUIPO DE PRESIÓN (MOTOBOMBA + TANQUE HIDROACUMULADOR)
A3: Proyecto: Vivienda campestre unifamiliar – Restrepo (Valle del Cauca) | Rev. 0 | PENDIENTE: ajustar con planos arquitectónicos (D:\trabajo\proyecto\en curso\casa Restrepo)
A6: 1. CAUDAL Y ALTURA DINÁMICA TOTAL
A7: Ítem | B7: Descripción | C7: Símbolo | D7: Valor | E7: Unidad | F7: Referencia normativa / criterio / observación
A8: 1.1 | B8: Caudal de bombeo = Q máximo probable de la red (Hunter) | C8: Qb | D8: =Tramos!$C$21 -> 1.4472892 | E8: L/s | F8: Hoja Tramos (tramo inicial)
A9: 1.2 | B9: Altura estática de succión (eje bomba − nivel mínimo tanque; + si succión negativa) | C9: Hs | D9: 1 | E9: m | F9: PENDIENTE: ajustar con planos arquitectónicos (D:\trabajo\proyecto\en curso\casa Restrepo)
A10: 1.3 | B10: Pérdidas en succión y descarga del equipo (accesorios, válvulas, cheque) | C10: hfs | D10: 1.5 | E10: m
A11: 1.4 | B11: Diferencial de presión arranque–paro | C11: ΔP | D11: 14.06 | E11: m.c.a. | F11: 20 psi (presostato 20–40 psi)
A12: 1.5 | B12: Presión de paro = P arranque + ΔP | C12: Pparo | D12: =Tramos!$C$11+$D$11 -> 28.12 | E12: m.c.a. | F12: P arranque en hoja Tramos
A13: 1.6 | B13: Altura dinámica total ADT = Hs + hfs + Pparo | C13: ADT | D13: =$D$9+$D$10+$D$12 -> 30.62 | E13: m
A14: 1.7 | B14: P arranque cubre Σhf + ΣΔz + Pmín de la ruta crítica | C14: ✓ | D14: =IF(Tramos!$C$11>=Tramos!$C$22+Tramos!$C$23+Tramos!$C$12,"CUMPLE","NO CUMPLE") -> CUMPLE | F14: Coherencia con hoja Tramos
A15: 1.8 | B15: Presión de paro ≤ 50 m.c.a. (protección de aparatos) | C15: ✓ | D15: =IF($D$12<=50,"CUMPLE","NO CUMPLE") -> CUMPLE | F15: NTC 1500 – presión máxima en aparatos
A17: 2. POTENCIA
A18: Ítem | B18: Descripción | C18: Símbolo | D18: Valor | E18: Unidad | F18: Referencia normativa / criterio / observación
A19: 2.1 | B19: Eficiencia del conjunto motobomba | C19: η | D19: 0.5 | F19: Curva del fabricante; típica 0,45–0,60 en equipos domésticos
A20: 2.2 | B20: Potencia = Qb · ADT / (76 · η) | C20: P | D20: =$D$8*$D$13/(76*$D$19) -> 1.1662104 | E20: HP | F20: Q en L/s, ADT en m
A21: 2.3 | B21: Potencia comercial seleccionada | C21: Pc | D21: =INDEX(Tablas!$A$76:$A$82,COUNTIF(Tablas!$A$76:$A$82,"<"&$D$20)+1) -> 1.5 | E21: HP | F21: Siguiente potencia comercial
A23: 3. TANQUE HIDROACUMULADOR
A24: Ítem | B24: Descripción | C24: Símbolo | D24: Valor | E24: Unidad | F24: Referencia normativa / criterio / observación
A25: 3.1 | B25: Número máximo de arranques por hora | C25: N | D25: 15 | E25: arr/h | F25: Ficha técnica del motor (≤ 1 HP: 15–20)
A26: 3.2 | B26: Duración del ciclo = 3.600 / N | C26: Tc | D26: =3600/$D$25 -> 240 | E26: s
A27: 3.3 | B27: Volumen útil = Qb · Tc / 4 | C27: Vu | D27: =$D$8*$D$26/4 -> 86.837351 | E27: L | F27: Criterio de ciclo de bombeo
A28: 3.4 | B28: Presión atmosférica local | C28: Patm | D28: =10.33*(1-0.0000225577*Datos!$D$13)^5.25588 -> 8.7267237 | E28: m.c.a. | F28: Atmósfera estándar a la altitud del predio
A29: 3.5 | B29: Volumen total = Vu · (Pparo + Patm) / (Pparo − Parr) | C29: Vh | D29: =$D$27*($D$12+$D$28)/($D$12-Tramos!$C$11) -> 227.57268 | E29: L | F29: Ley de Boyle (presiones absolutas)
A30: 3.6 | B30: Volumen del hidroacumulador comercial seleccionado | C30: Vhc | D30: 300 | E30: L | F30: Alternativa: equipo de velocidad variable con tanque según fabricante
A31: 3.7 | B31: Volumen comercial ≥ volumen requerido | C31: ✓ | D31: =IF($D$30>=$D$29,"CUMPLE","NO CUMPLE") -> CUMPLE

Sheet Resumen
A1: MEMORIA DE CÁLCULO – INSTALACIONES HIDRÁULICAS DE AGUA POTABLE
A2: RESUMEN DE RESULTADOS Y VERIFICACIONES
A3: Proyecto: Vivienda campestre unifamiliar – Restrepo (Valle del Cauca) | Rev. 0 | PENDIENTE: ajustar con planos arquitectónicos (D:\trabajo\proyecto\en curso\casa Restrepo)
A6: 1. RESULTADOS PRINCIPALES
A7: Ítem | B7: Descripción | C7: Símbolo | D7: Valor | E7: Unidad | F7: Referencia normativa / criterio / observación
A8: 1.1 | B8: Nivel de complejidad (RAS 2000) | D8: =Poblacion!$D$26 -> BAJO
A9: 1.2 | B9: Población con pernoctación (diseño) | D9: =Poblacion!$D$19 -> 11 | E9: hab
A10: 1.3 | B10: Población flotante diurna (empleados) | D10: =Poblacion!$D$20 -> 2 | E10: emp
A11: 1.4 | B11: Población total de diseño | D11: =Poblacion!$D$21 -> 13 | E11: hab
A12: 1.5 | B12: Dotación neta adoptada – residencial | D12: =Poblacion!$D$38 -> 130 | E12: L/hab·d
A13: 1.6 | B13: Consumo neto total | D13: =Poblacion!$E$47 -> 1530 | E13: L/d
A14: 1.7 | B14: Caudal medio diario Qmd | D14: =Dotacion_Caudales!$D$26 -> 0.030555556 | E14: L/s
A15: 1.8 | B15: Caudal máximo diario QMD | D15: =Dotacion_Caudales!$D$29 -> 0.039722222 | E15: L/s
A16: 1.9 | B16: Caudal máximo horario QMH | D16: =Dotacion_Caudales!$D$31 -> 0.063555556 | E16: L/s
A17: 1.10 | B17: Volumen de reserva requerido | D17: =Almacenamiento!$D$12 -> 2130 | E17: L
A18: 1.11 | B18: Volumen de reserva instalado | D18: =Almacenamiento!$D$18 -> 4000 | E18: L
A19: 1.12 | B19: Unidades de consumo totales | D19: =UC_Hunter!$D$18 -> 29 | E19: UC
A20: 1.13 | B20: Caudal máximo probable (Hunter) | D20: =UC_Hunter!$D$20 -> 1.4472892 | E20: L/s
A21: 1.14 | B21: Presión residual en aparato crítico | D21: =Tramos!$C$24 -> 8.2220044 | E21: m.c.a.
A22: 1.15 | B22: Diámetro de acometida | D22: =Acometida_Medidor!$D$13 -> 3/4"
A23: 1.16 | B23: Caudal de acometida | D23: =Acometida_Medidor!$D$18 -> 0.18518519 | E23: L/s
A24: 1.17 | B24: Altura dinámica total del equipo | D24: =Equipo_Presion!$D$13 -> 30.62 | E24: m
A25: 1.18 | B25: Potencia comercial de motobomba | D25: =Equipo_Presion!$D$21 -> 1.5 | E25: HP
A26: 1.19 | B26: Volumen de hidroacumulador requerido | D26: =Equipo_Presion!$D$29 -> 227.57268 | E26: L
A28: 2. VERIFICACIONES NORMATIVAS Y DE CRITERIO
A29: Ítem | B29: Verificación | C29: Hoja | D29: Resultado | F29: Observación
A30: 1 | B30: Dotación base dentro del rango RAS 2000 | C30: Poblacion | D30: =Poblacion!$D$34 -> CUMPLE
A31: 2 | B31: Pérdidas adoptadas ≤ 25 % (Res. 0330/2017) | C31: Dotacion_Caudales | D31: =Dotacion_Caudales!$D$10 -> CUMPLE
A32: 3 | B32: Volumen instalado ≥ volumen requerido | C32: Almacenamiento | D32: =Almacenamiento!$D$19 -> CUMPLE
A33: 4 | B33: Velocidad ≤ Vmáx en todos los tramos | C33: Tramos | D33: =Tramos!$C$27 -> CUMPLE
A34: 5 | B34: Presión residual ≥ presión mínima en la ruta crítica | C34: Tramos | D34: =Tramos!$C$28 -> CUMPLE
A35: 6 | B35: Velocidad en acometida ≤ Vmáx | C35: Acometida_Medidor | D35: =Acometida_Medidor!$D$21 -> CUMPLE
A36: 7 | B36: Presión en flotador ≥ mínima | C36: Acometida_Medidor | D36: =Acometida_Medidor!$D$24 -> CUMPLE
A37: 8 | B37: Caudal de acometida ≤ Q3 del medidor | C37: Acometida_Medidor | D37: =Acometida_Medidor!$D$30 -> CUMPLE
A38: 9 | B38: P arranque cubre Σhf + ΣΔz + Pmín de la ruta crítica | C38: Equipo_Presion | D38: =Equipo_Presion!$D$14 -> CUMPLE
A39: 10 | B39: Presión de paro ≤ 50 m.c.a. (protección de aparatos) | C39: Equipo_Presion | D39: =Equipo_Presion!$D$15 -> CUMPLE
A40: 11 | B40: Volumen comercial ≥ volumen requerido | C40: Equipo_Presion | D40: =Equipo_Presion!$D$31 -> CUMPLE
A42: 2.1 | B42: Número de verificaciones que NO CUMPLEN | C42: n | D42: =COUNTIF(D30:D40,"NO CUMPLE") -> 0 | F42: Debe ser 0 para aprobar el diseño
A43: 2.2 | B43: ESTADO GLOBAL DEL DISEÑO | C43: ✓ | D43: =IF($D$42=0,"CUMPLE","NO CUMPLE") -> CUMPLE | F43: Todas las verificaciones deben cumplir

Sheet Tablas
A1: MEMORIA DE CÁLCULO – INSTALACIONES HIDRÁULICAS DE AGUA POTABLE
A2: TABLAS DE REFERENCIA
A3: Proyecto: Vivienda campestre unifamiliar – Restrepo (Valle del Cauca) | Rev. 0 | PENDIENTE: ajustar con planos arquitectónicos (D:\trabajo\proyecto\en curso\casa Restrepo)
A6: 1. CURVA DE HUNTER – GASTO PROBABLE (TANQUE)
B7: Hunter (1940). Fuente: IPC Tabla E103.3(3), aparatos con tanque. Conversión 1 gpm = 0,0631 L/s. Método de gastos probables aceptado por NTC 1500.
A8: Unidades (UC / UD) | B8: Q (gpm) | C8: Q (L/s)
A9: 1 | B9: 3 | C9: =B9*0.0630902 -> 0.1892706
A10: 2 | B10: 5 | C10: =B10*0.0630902 -> 0.315451
A11: 3 | B11: 6.5 | C11: =B11*0.0630902 -> 0.4100863
A12: 4 | B12: 8 | C12: =B12*0.0630902 -> 0.5047216
A13: 5 | B13: 9.4 | C13: =B13*0.0630902 -> 0.59304788
A14: 6 | B14: 10.7 | C14: =B14*0.0630902 -> 0.67506514
A15: 7 | B15: 11.8 | C15: =B15*0.0630902 -> 0.74446436
A16: 8 | B16: 12.8 | C16: =B16*0.0630902 -> 0.80755456
A17: 9 | B17: 13.7 | C17: =B17*0.0630902 -> 0.86433574
A18: 10 | B18: 14.6 | C18: =B18*0.0630902 -> 0.92111692
A19: 11 | B19: 15.4 | C19: =B19*0.0630902 -> 0.97158908
A20: 12 | B20: 16 | C20: =B20*0.0630902 -> 1.0094432
... A44: 200 | B44: 65 | C44: =B44*0.0630902 -> 4.100863
A46: 2. RAS 2000 – NIVEL DE COMPLEJIDAD Y PARÁMETROS ASOCIADOS
B47: Tabla A.3.1 (nivel por población), B.2.2 (dotación neta mín./máx.), B.2.4 (pérdidas técnicas máx.), B.2.5 (k1), B.2.6 (k2, red menor de distribución), período de diseño (RAS 2000).
A48: Nivel | B48: Población desde (hab) | C48: Dot. neta mín. (L/hab·d) | D48: Dot. neta máx. (L/hab·d) | E48: % pérdidas máx. | F48: k1 | G48: k2 | H48: Período diseño (años)
A49: BAJO | B49: 0 | C49: 100 | D49: 150 | E49: 0.4 | F49: 1.3 | G49: 1.6 | H49: 15
A50: MEDIO | B50: 2501 | C50: 120 | D50: 175 | E50: 0.3 | F50: 1.3 | G50: 1.6 | H50: 20
A51: MEDIO ALTO | B51: 12501 | C51: 130 | D51: 175 | E51: 0.25 | F51: 1.2 | G51: 1.5 | H51: 25
A52: ALTO | B52: 60001 | C52: 150 | D52: 200 | E52: 0.2 | F52: 1.2 | G52: 1.5 | H52: 30
A54: 3. TUBERÍA PVC PRESIÓN – DIÁMETROS INTERNOS
B55: Valores típicos de catálogo PVC presión (NTC 382). Verificar con el fabricante seleccionado.
A56: Ø nominal | B56: RDE | C56: Ø externo (mm) | D56: Espesor (mm) | E56: Ø interno (mm)
A57: 1/2" | B57: RDE 13,5 | C57: 21.34 | D57: 1.58 | E57: =C57-2*D57 -> 18.18
A58: 3/4" | B58: RDE 21 | C58: 26.67 | D58: 1.27 | E58: =C58-2*D58 -> 24.13
A59: 1" | B59: RDE 21 | C59: 33.4 | D59: 1.59 | E59: =C59-2*D59 -> 30.22
A60: 1-1/4" | B60: RDE 21 | C60: 42.16 | D60: 2.01 | E60: =C60-2*D60 -> 38.14
A61: 1-1/2" | B61: RDE 21 | C61: 48.26 | D61: 2.3 | E61: =C61-2*D61 -> 43.66
A62: 2" | B62: RDE 21 | C62: 60.32 | D62: 2.87 | E62: =C62-2*D62 -> 54.58
A64: 4. MEDIDORES – CAUDAL PERMANENTE Q3
B65: NTC 1063-1 (ISO 4064-1). Valores típicos de Q3 por diámetro; verificar con ficha técnica del medidor exigido por el prestador.
A66: Ø nominal | B66: Q3 (m³/h)
A67: 1/2" | B67: 2.5
A68: 3/4" | B68: 4
...
